2025-02-26 13:06:46,260 data_to_fw.py ERROR: File /home/factana/object_tracking/order_status_payloads/.gitkeep is empty. Removing.
2025-02-26 13:06:49,535 data_to_fw.py ERROR: Error : HTTPConnectionPool(host='127.0.0.1', port=7077): Max retries exceeded with url: /fwvision/qcinspection/update_qc_order (Caused by NewConnectionError('<urllib3.connection.HTTPConnection object at 0xffffb18b8490>: Failed to establish a new connection: [Errno 111] Connection refused'))
2025-02-26 13:06:53,372 data_to_fw.py ERROR: Error : HTTPConnectionPool(host='127.0.0.1', port=7077): Max retries exceeded with url: /fwvision/qcinspection/update_qc_order (Caused by NewConnectionError('<urllib3.connection.HTTPConnection object at 0xffffb18b8ee0>: Failed to establish a new connection: [Errno 111] Connection refused'))
2025-02-26 13:06:57,082 data_to_fw.py ERROR: Error : HTTPConnectionPool(host='127.0.0.1', port=7077): Max retries exceeded with url: /fwvision/qcinspection/update_qc_order (Caused by NewConnectionError('<urllib3.connection.HTTPConnection object at 0xffffb18b88b0>: Failed to establish a new connection: [Errno 111] Connection refused'))
2025-02-26 13:07:00,794 data_to_fw.py ERROR: Error : HTTPConnectionPool(host='127.0.0.1', port=7077): Max retries exceeded with url: /fwvision/qcinspection/update_qc_order (Caused by NewConnectionError('<urllib3.connection.HTTPConnection object at 0xffffb2999820>: Failed to establish a new connection: [Errno 111] Connection refused'))
2025-02-26 13:07:04,793 data_to_fw.py ERROR: Error : HTTPConnectionPool(host='127.0.0.1', port=7077): Max retries exceeded with url: /fwvision/qcinspection/update_qc_order (Caused by NewConnectionError('<urllib3.connection.HTTPConnection object at 0xffffb18d6910>: Failed to establish a new connection: [Errno 111] Connection refused'))
2025-02-26 13:07:08,490 data_to_fw.py ERROR: Error : HTTPConnectionPool(host='127.0.0.1', port=7077): Max retries exceeded with url: /fwvision/qcinspection/update_qc_order (Caused by NewConnectionError('<urllib3.connection.HTTPConnection object at 0xffffb18df340>: Failed to establish a new connection: [Errno 111] Connection refused'))
2025-02-26 13:09:48,269 data_to_fw.py ERROR: Error : HTTPConnectionPool(host='127.0.0.1', port=7077): Max retries exceeded with url: /fwvision/qcinspection/update_qc_order (Caused by NewConnectionError('<urllib3.connection.HTTPConnection object at 0xffffac617d60>: Failed to establish a new connection: [Errno 111] Connection refused'))
2025-02-26 13:09:51,973 data_to_fw.py ERROR: Error : HTTPConnectionPool(host='127.0.0.1', port=7077): Max retries exceeded with url: /fwvision/qcinspection/update_qc_order (Caused by NewConnectionError('<urllib3.connection.HTTPConnection object at 0xffffac63b820>: Failed to establish a new connection: [Errno 111] Connection refused'))
2025-02-26 13:09:55,704 data_to_fw.py ERROR: Error : HTTPConnectionPool(host='127.0.0.1', port=7077): Max retries exceeded with url: /fwvision/qcinspection/update_qc_order (Caused by NewConnectionError('<urllib3.connection.HTTPConnection object at 0xffffac617c70>: Failed to establish a new connection: [Errno 111] Connection refused'))
2025-02-26 13:09:59,404 data_to_fw.py ERROR: Error : HTTPConnectionPool(host='127.0.0.1', port=7077): Max retries exceeded with url: /fwvision/qcinspection/update_qc_order (Caused by NewConnectionError('<urllib3.connection.HTTPConnection object at 0xffffac63b520>: Failed to establish a new connection: [Errno 111] Connection refused'))
2025-02-26 13:10:03,400 data_to_fw.py ERROR: Error : HTTPConnectionPool(host='127.0.0.1', port=7077): Max retries exceeded with url: /fwvision/qcinspection/update_qc_order (Caused by NewConnectionError('<urllib3.connection.HTTPConnection object at 0xffffac644250>: Failed to establish a new connection: [Errno 111] Connection refused'))
2025-02-26 13:10:07,096 data_to_fw.py ERROR: Error : HTTPConnectionPool(host='127.0.0.1', port=7077): Max retries exceeded with url: /fwvision/qcinspection/update_qc_order (Caused by NewConnectionError('<urllib3.connection.HTTPConnection object at 0xffffac644c40>: Failed to establish a new connection: [Errno 111] Connection refused'))
2025-02-26 13:10:10,787 data_to_fw.py ERROR: Error : HTTPConnectionPool(host='127.0.0.1', port=7077): Max retries exceeded with url: /fwvision/qcinspection/update_qc_order (Caused by NewConnectionError('<urllib3.connection.HTTPConnection object at 0xffffac5ac670>: Failed to establish a new connection: [Errno 111] Connection refused'))
2025-02-26 13:10:14,477 data_to_fw.py ERROR: Error : HTTPConnectionPool(host='127.0.0.1', port=7077): Max retries exceeded with url: /fwvision/qcinspection/update_qc_order (Caused by NewConnectionError('<urllib3.connection.HTTPConnection object at 0xffffac6440a0>: Failed to establish a new connection: [Errno 111] Connection refused'))
2025-02-26 13:10:18,474 data_to_fw.py ERROR: Error : HTTPConnectionPool(host='127.0.0.1', port=7077): Max retries exceeded with url: /fwvision/qcinspection/update_qc_order (Caused by NewConnectionError('<urllib3.connection.HTTPConnection object at 0xffffac63b550>: Failed to establish a new connection: [Errno 111] Connection refused'))
2025-02-26 13:10:22,177 data_to_fw.py ERROR: Error : HTTPConnectionPool(host='127.0.0.1', port=7077): Max retries exceeded with url: /fwvision/qcinspection/update_qc_order (Caused by NewConnectionError('<urllib3.connection.HTTPConnection object at 0xffffac617cd0>: Failed to establish a new connection: [Errno 111] Connection refused'))
2025-02-26 13:10:25,875 data_to_fw.py ERROR: Error : HTTPConnectionPool(host='127.0.0.1', port=7077): Max retries exceeded with url: /fwvision/qcinspection/update_qc_order (Caused by NewConnectionError('<urllib3.connection.HTTPConnection object at 0xffffacee1f10>: Failed to establish a new connection: [Errno 111] Connection refused'))
2025-02-26 13:10:29,583 data_to_fw.py ERROR: Error : HTTPConnectionPool(host='127.0.0.1', port=7077): Max retries exceeded with url: /fwvision/qcinspection/update_qc_order (Caused by NewConnectionError('<urllib3.connection.HTTPConnection object at 0xffffac5b90a0>: Failed to establish a new connection: [Errno 111] Connection refused'))
2025-02-26 13:10:33,580 data_to_fw.py ERROR: Error : HTTPConnectionPool(host='127.0.0.1', port=7077): Max retries exceeded with url: /fwvision/qcinspection/update_qc_order (Caused by NewConnectionError('<urllib3.connection.HTTPConnection object at 0xffffac63b580>: Failed to establish a new connection: [Errno 111] Connection refused'))
2025-02-26 13:10:37,285 data_to_fw.py ERROR: Error : HTTPConnectionPool(host='127.0.0.1', port=7077): Max retries exceeded with url: /fwvision/qcinspection/update_qc_order (Caused by NewConnectionError('<urllib3.connection.HTTPConnection object at 0xffffac63bd60>: Failed to establish a new connection: [Errno 111] Connection refused'))
2025-02-26 13:10:40,982 data_to_fw.py ERROR: Error : HTTPConnectionPool(host='127.0.0.1', port=7077): Max retries exceeded with url: /fwvision/qcinspection/update_qc_order (Caused by NewConnectionError('<urllib3.connection.HTTPConnection object at 0xffffac5ac040>: Failed to establish a new connection: [Errno 111] Connection refused'))
2025-02-26 13:10:44,687 data_to_fw.py ERROR: Error : HTTPConnectionPool(host='127.0.0.1', port=7077): Max retries exceeded with url: /fwvision/qcinspection/update_qc_order (Caused by NewConnectionError('<urllib3.connection.HTTPConnection object at 0xffffac6448e0>: Failed to establish a new connection: [Errno 111] Connection refused'))
2025-02-26 13:10:48,689 data_to_fw.py ERROR: Error : HTTPConnectionPool(host='127.0.0.1', port=7077): Max retries exceeded with url: /fwvision/qcinspection/update_qc_order (Caused by NewConnectionError('<urllib3.connection.HTTPConnection object at 0xffffac644f10>: Failed to establish a new connection: [Errno 111] Connection refused'))
2025-02-26 13:10:52,391 data_to_fw.py ERROR: Error : HTTPConnectionPool(host='127.0.0.1', port=7077): Max retries exceeded with url: /fwvision/qcinspection/update_qc_order (Caused by NewConnectionError('<urllib3.connection.HTTPConnection object at 0xffffac6441c0>: Failed to establish a new connection: [Errno 111] Connection refused'))
2025-02-26 13:10:56,098 data_to_fw.py ERROR: Error : HTTPConnectionPool(host='127.0.0.1', port=7077): Max retries exceeded with url: /fwvision/qcinspection/update_qc_order (Caused by NewConnectionError('<urllib3.connection.HTTPConnection object at 0xffffac5ac070>: Failed to establish a new connection: [Errno 111] Connection refused'))
2025-02-26 13:10:59,814 data_to_fw.py ERROR: Error : HTTPConnectionPool(host='127.0.0.1', port=7077): Max retries exceeded with url: /fwvision/qcinspection/update_qc_order (Caused by NewConnectionError('<urllib3.connection.HTTPConnection object at 0xffffac63bd60>: Failed to establish a new connection: [Errno 111] Connection refused'))
2025-02-26 13:11:03,809 data_to_fw.py ERROR: Error : HTTPConnectionPool(host='127.0.0.1', port=7077): Max retries exceeded with url: /fwvision/qcinspection/update_qc_order (Caused by NewConnectionError('<urllib3.connection.HTTPConnection object at 0xffffac63bb20>: Failed to establish a new connection: [Errno 111] Connection refused'))
2025-02-26 13:11:07,519 data_to_fw.py ERROR: Error : HTTPConnectionPool(host='127.0.0.1', port=7077): Max retries exceeded with url: /fwvision/qcinspection/update_qc_order (Caused by NewConnectionError('<urllib3.connection.HTTPConnection object at 0xffffacee1e50>: Failed to establish a new connection: [Errno 111] Connection refused'))
2025-02-26 13:11:11,235 data_to_fw.py ERROR: Error : HTTPConnectionPool(host='127.0.0.1', port=7077): Max retries exceeded with url: /fwvision/qcinspection/update_qc_order (Caused by NewConnectionError('<urllib3.connection.HTTPConnection object at 0xffffac617130>: Failed to establish a new connection: [Errno 111] Connection refused'))
2025-02-26 13:11:14,927 data_to_fw.py ERROR: Error : HTTPConnectionPool(host='127.0.0.1', port=7077): Max retries exceeded with url: /fwvision/qcinspection/update_qc_order (Caused by NewConnectionError('<urllib3.connection.HTTPConnection object at 0xffffac63b400>: Failed to establish a new connection: [Errno 111] Connection refused'))
2025-02-26 13:11:18,923 data_to_fw.py ERROR: Error : HTTPConnectionPool(host='127.0.0.1', port=7077): Max retries exceeded with url: /fwvision/qcinspection/update_qc_order (Caused by NewConnectionError('<urllib3.connection.HTTPConnection object at 0xffffac63bdf0>: Failed to establish a new connection: [Errno 111] Connection refused'))
2025-02-26 13:11:22,623 data_to_fw.py ERROR: Error : HTTPConnectionPool(host='127.0.0.1', port=7077): Max retries exceeded with url: /fwvision/qcinspection/update_qc_order (Caused by NewConnectionError('<urllib3.connection.HTTPConnection object at 0xffffacee1910>: Failed to establish a new connection: [Errno 111] Connection refused'))
2025-02-26 13:11:26,336 data_to_fw.py ERROR: Error : HTTPConnectionPool(host='127.0.0.1', port=7077): Max retries exceeded with url: /fwvision/qcinspection/update_qc_order (Caused by NewConnectionError('<urllib3.connection.HTTPConnection object at 0xffffac644460>: Failed to establish a new connection: [Errno 111] Connection refused'))
2025-02-26 13:11:30,038 data_to_fw.py ERROR: Error : HTTPConnectionPool(host='127.0.0.1', port=7077): Max retries exceeded with url: /fwvision/qcinspection/update_qc_order (Caused by NewConnectionError('<urllib3.connection.HTTPConnection object at 0xffffac5b9af0>: Failed to establish a new connection: [Errno 111] Connection refused'))
2025-02-26 13:11:34,027 data_to_fw.py ERROR: Error : HTTPConnectionPool(host='127.0.0.1', port=7077): Max retries exceeded with url: /fwvision/qcinspection/update_qc_order (Caused by NewConnectionError('<urllib3.connection.HTTPConnection object at 0xffffac63baf0>: Failed to establish a new connection: [Errno 111] Connection refused'))
2025-02-26 13:11:37,728 data_to_fw.py ERROR: Error : HTTPConnectionPool(host='127.0.0.1', port=7077): Max retries exceeded with url: /fwvision/qcinspection/update_qc_order (Caused by NewConnectionError('<urllib3.connection.HTTPConnection object at 0xffffac63b8b0>: Failed to establish a new connection: [Errno 111] Connection refused'))
2025-02-26 13:11:41,431 data_to_fw.py ERROR: Error : HTTPConnectionPool(host='127.0.0.1', port=7077): Max retries exceeded with url: /fwvision/qcinspection/update_qc_order (Caused by NewConnectionError('<urllib3.connection.HTTPConnection object at 0xffffacee19a0>: Failed to establish a new connection: [Errno 111] Connection refused'))
2025-02-26 13:11:45,134 data_to_fw.py ERROR: Error : HTTPConnectionPool(host='127.0.0.1', port=7077): Max retries exceeded with url: /fwvision/qcinspection/update_qc_order (Caused by NewConnectionError('<urllib3.connection.HTTPConnection object at 0xffffac5ac220>: Failed to establish a new connection: [Errno 111] Connection refused'))
2025-02-26 13:11:49,135 data_to_fw.py ERROR: Error : HTTPConnectionPool(host='127.0.0.1', port=7077): Max retries exceeded with url: /fwvision/qcinspection/update_qc_order (Caused by NewConnectionError('<urllib3.connection.HTTPConnection object at 0xffffac617cd0>: Failed to establish a new connection: [Errno 111] Connection refused'))
2025-02-26 13:11:52,831 data_to_fw.py ERROR: Error : HTTPConnectionPool(host='127.0.0.1', port=7077): Max retries exceeded with url: /fwvision/qcinspection/update_qc_order (Caused by NewConnectionError('<urllib3.connection.HTTPConnection object at 0xffffac5acd60>: Failed to establish a new connection: [Errno 111] Connection refused'))
2025-02-26 13:11:56,519 data_to_fw.py ERROR: Error : HTTPConnectionPool(host='127.0.0.1', port=7077): Max retries exceeded with url: /fwvision/qcinspection/update_qc_order (Caused by NewConnectionError('<urllib3.connection.HTTPConnection object at 0xffffacee17f0>: Failed to establish a new connection: [Errno 111] Connection refused'))
2025-02-26 13:12:00,210 data_to_fw.py ERROR: Error : HTTPConnectionPool(host='127.0.0.1', port=7077): Max retries exceeded with url: /fwvision/qcinspection/update_qc_order (Caused by NewConnectionError('<urllib3.connection.HTTPConnection object at 0xffffac63b250>: Failed to establish a new connection: [Errno 111] Connection refused'))
2025-02-26 13:12:04,206 data_to_fw.py ERROR: Error : HTTPConnectionPool(host='127.0.0.1', port=7077): Max retries exceeded with url: /fwvision/qcinspection/update_qc_order (Caused by NewConnectionError('<urllib3.connection.HTTPConnection object at 0xffffac63bdf0>: Failed to establish a new connection: [Errno 111] Connection refused'))
2025-02-26 13:12:07,910 data_to_fw.py ERROR: Error : HTTPConnectionPool(host='127.0.0.1', port=7077): Max retries exceeded with url: /fwvision/qcinspection/update_qc_order (Caused by NewConnectionError('<urllib3.connection.HTTPConnection object at 0xffffac6440d0>: Failed to establish a new connection: [Errno 111] Connection refused'))
2025-02-26 13:12:11,630 data_to_fw.py ERROR: Error : HTTPConnectionPool(host='127.0.0.1', port=7077): Max retries exceeded with url: /fwvision/qcinspection/update_qc_order (Caused by NewConnectionError('<urllib3.connection.HTTPConnection object at 0xffffac5b9370>: Failed to establish a new connection: [Errno 111] Connection refused'))
2025-02-26 13:12:15,318 data_to_fw.py ERROR: Error : HTTPConnectionPool(host='127.0.0.1', port=7077): Max retries exceeded with url: /fwvision/qcinspection/update_qc_order (Caused by NewConnectionError('<urllib3.connection.HTTPConnection object at 0xffffac63baf0>: Failed to establish a new connection: [Errno 111] Connection refused'))
2025-02-26 13:12:19,317 data_to_fw.py ERROR: Error : HTTPConnectionPool(host='127.0.0.1', port=7077): Max retries exceeded with url: /fwvision/qcinspection/update_qc_order (Caused by NewConnectionError('<urllib3.connection.HTTPConnection object at 0xffffac63ba00>: Failed to establish a new connection: [Errno 111] Connection refused'))
2025-02-26 13:12:23,025 data_to_fw.py ERROR: Error : HTTPConnectionPool(host='127.0.0.1', port=7077): Max retries exceeded with url: /fwvision/qcinspection/update_qc_order (Caused by NewConnectionError('<urllib3.connection.HTTPConnection object at 0xffffac644070>: Failed to establish a new connection: [Errno 111] Connection refused'))
2025-02-26 13:12:26,733 data_to_fw.py ERROR: Error : HTTPConnectionPool(host='127.0.0.1', port=7077): Max retries exceeded with url: /fwvision/qcinspection/update_qc_order (Caused by NewConnectionError('<urllib3.connection.HTTPConnection object at 0xffffac5ac280>: Failed to establish a new connection: [Errno 111] Connection refused'))
2025-02-26 13:12:30,448 data_to_fw.py ERROR: Error : HTTPConnectionPool(host='127.0.0.1', port=7077): Max retries exceeded with url: /fwvision/qcinspection/update_qc_order (Caused by NewConnectionError('<urllib3.connection.HTTPConnection object at 0xffffac5ac8e0>: Failed to establish a new connection: [Errno 111] Connection refused'))
2025-02-26 13:12:34,461 data_to_fw.py ERROR: Error : HTTPConnectionPool(host='127.0.0.1', port=7077): Max retries exceeded with url: /fwvision/qcinspection/update_qc_order (Caused by NewConnectionError('<urllib3.connection.HTTPConnection object at 0xffffac5ac700>: Failed to establish a new connection: [Errno 111] Connection refused'))
2025-02-26 13:12:38,166 data_to_fw.py ERROR: Error : HTTPConnectionPool(host='127.0.0.1', port=7077): Max retries exceeded with url: /fwvision/qcinspection/update_qc_order (Caused by NewConnectionError('<urllib3.connection.HTTPConnection object at 0xffffac644040>: Failed to establish a new connection: [Errno 111] Connection refused'))
2025-02-26 13:12:41,856 data_to_fw.py ERROR: Error : HTTPConnectionPool(host='127.0.0.1', port=7077): Max retries exceeded with url: /fwvision/qcinspection/update_qc_order (Caused by NewConnectionError('<urllib3.connection.HTTPConnection object at 0xffffac63b9d0>: Failed to establish a new connection: [Errno 111] Connection refused'))
2025-02-26 13:12:45,564 data_to_fw.py ERROR: Error : HTTPConnectionPool(host='127.0.0.1', port=7077): Max retries exceeded with url: /fwvision/qcinspection/update_qc_order (Caused by NewConnectionError('<urllib3.connection.HTTPConnection object at 0xffffac63bfd0>: Failed to establish a new connection: [Errno 111] Connection refused'))
2025-02-26 13:12:49,558 data_to_fw.py ERROR: Error : HTTPConnectionPool(host='127.0.0.1', port=7077): Max retries exceeded with url: /fwvision/qcinspection/update_qc_order (Caused by NewConnectionError('<urllib3.connection.HTTPConnection object at 0xffffacee16d0>: Failed to establish a new connection: [Errno 111] Connection refused'))
2025-02-26 13:12:53,261 data_to_fw.py ERROR: Error : HTTPConnectionPool(host='127.0.0.1', port=7077): Max retries exceeded with url: /fwvision/qcinspection/update_qc_order (Caused by NewConnectionError('<urllib3.connection.HTTPConnection object at 0xffffac644130>: Failed to establish a new connection: [Errno 111] Connection refused'))
2025-02-26 13:12:56,961 data_to_fw.py ERROR: Error : HTTPConnectionPool(host='127.0.0.1', port=7077): Max retries exceeded with url: /fwvision/qcinspection/update_qc_order (Caused by NewConnectionError('<urllib3.connection.HTTPConnection object at 0xffffac63b070>: Failed to establish a new connection: [Errno 111] Connection refused'))
2025-02-26 13:13:00,658 data_to_fw.py ERROR: Error : HTTPConnectionPool(host='127.0.0.1', port=7077): Max retries exceeded with url: /fwvision/qcinspection/update_qc_order (Caused by NewConnectionError('<urllib3.connection.HTTPConnection object at 0xffffac63b8b0>: Failed to establish a new connection: [Errno 111] Connection refused'))
2025-02-26 13:13:04,669 data_to_fw.py ERROR: Error : HTTPConnectionPool(host='127.0.0.1', port=7077): Max retries exceeded with url: /fwvision/qcinspection/update_qc_order (Caused by NewConnectionError('<urllib3.connection.HTTPConnection object at 0xffffacee1940>: Failed to establish a new connection: [Errno 111] Connection refused'))
2025-02-26 13:13:08,363 data_to_fw.py ERROR: Error : HTTPConnectionPool(host='127.0.0.1', port=7077): Max retries exceeded with url: /fwvision/qcinspection/update_qc_order (Caused by NewConnectionError('<urllib3.connection.HTTPConnection object at 0xffffac5ac5b0>: Failed to establish a new connection: [Errno 111] Connection refused'))
2025-02-26 13:13:12,072 data_to_fw.py ERROR: Error : HTTPConnectionPool(host='127.0.0.1', port=7077): Max retries exceeded with url: /fwvision/qcinspection/update_qc_order (Caused by NewConnectionError('<urllib3.connection.HTTPConnection object at 0xffffac5c44f0>: Failed to establish a new connection: [Errno 111] Connection refused'))
2025-02-26 13:13:15,773 data_to_fw.py ERROR: Error : HTTPConnectionPool(host='127.0.0.1', port=7077): Max retries exceeded with url: /fwvision/qcinspection/update_qc_order (Caused by NewConnectionError('<urllib3.connection.HTTPConnection object at 0xffffac63bfa0>: Failed to establish a new connection: [Errno 111] Connection refused'))
2025-02-26 13:13:19,768 data_to_fw.py ERROR: Error : HTTPConnectionPool(host='127.0.0.1', port=7077): Max retries exceeded with url: /fwvision/qcinspection/update_qc_order (Caused by NewConnectionError('<urllib3.connection.HTTPConnection object at 0xffffac63b790>: Failed to establish a new connection: [Errno 111] Connection refused'))
2025-02-26 13:13:23,461 data_to_fw.py ERROR: Error : HTTPConnectionPool(host='127.0.0.1', port=7077): Max retries exceeded with url: /fwvision/qcinspection/update_qc_order (Caused by NewConnectionError('<urllib3.connection.HTTPConnection object at 0xffffacee1b80>: Failed to establish a new connection: [Errno 111] Connection refused'))
2025-02-26 13:13:27,165 data_to_fw.py ERROR: Error : HTTPConnectionPool(host='127.0.0.1', port=7077): Max retries exceeded with url: /fwvision/qcinspection/update_qc_order (Caused by NewConnectionError('<urllib3.connection.HTTPConnection object at 0xffffac5b9eb0>: Failed to establish a new connection: [Errno 111] Connection refused'))
2025-02-26 13:13:30,881 data_to_fw.py ERROR: Error : HTTPConnectionPool(host='127.0.0.1', port=7077): Max retries exceeded with url: /fwvision/qcinspection/update_qc_order (Caused by NewConnectionError('<urllib3.connection.HTTPConnection object at 0xffffac5c4040>: Failed to establish a new connection: [Errno 111] Connection refused'))
2025-02-26 13:13:34,882 data_to_fw.py ERROR: Error : HTTPConnectionPool(host='127.0.0.1', port=7077): Max retries exceeded with url: /fwvision/qcinspection/update_qc_order (Caused by NewConnectionError('<urllib3.connection.HTTPConnection object at 0xffffac5b9040>: Failed to establish a new connection: [Errno 111] Connection refused'))
2025-02-26 13:13:38,589 data_to_fw.py ERROR: Error : HTTPConnectionPool(host='127.0.0.1', port=7077): Max retries exceeded with url: /fwvision/qcinspection/update_qc_order (Caused by NewConnectionError('<urllib3.connection.HTTPConnection object at 0xffffacee1dc0>: Failed to establish a new connection: [Errno 111] Connection refused'))
2025-02-26 13:13:42,283 data_to_fw.py ERROR: Error : HTTPConnectionPool(host='127.0.0.1', port=7077): Max retries exceeded with url: /fwvision/qcinspection/update_qc_order (Caused by NewConnectionError('<urllib3.connection.HTTPConnection object at 0xffffac63b670>: Failed to establish a new connection: [Errno 111] Connection refused'))
2025-02-26 13:13:45,977 data_to_fw.py ERROR: Error : HTTPConnectionPool(host='127.0.0.1', port=7077): Max retries exceeded with url: /fwvision/qcinspection/update_qc_order (Caused by NewConnectionError('<urllib3.connection.HTTPConnection object at 0xffffac5ac280>: Failed to establish a new connection: [Errno 111] Connection refused'))
2025-02-26 13:13:49,971 data_to_fw.py ERROR: Error : HTTPConnectionPool(host='127.0.0.1', port=7077): Max retries exceeded with url: /fwvision/qcinspection/update_qc_order (Caused by NewConnectionError('<urllib3.connection.HTTPConnection object at 0xffffac5c4790>: Failed to establish a new connection: [Errno 111] Connection refused'))
2025-02-26 13:13:53,681 data_to_fw.py ERROR: Error : HTTPConnectionPool(host='127.0.0.1', port=7077): Max retries exceeded with url: /fwvision/qcinspection/update_qc_order (Caused by NewConnectionError('<urllib3.connection.HTTPConnection object at 0xffffacee1910>: Failed to establish a new connection: [Errno 111] Connection refused'))
2025-02-26 13:13:57,373 data_to_fw.py ERROR: Error : HTTPConnectionPool(host='127.0.0.1', port=7077): Max retries exceeded with url: /fwvision/qcinspection/update_qc_order (Caused by NewConnectionError('<urllib3.connection.HTTPConnection object at 0xffffac63bd60>: Failed to establish a new connection: [Errno 111] Connection refused'))
2025-02-26 13:14:01,070 data_to_fw.py ERROR: Error : HTTPConnectionPool(host='127.0.0.1', port=7077): Max retries exceeded with url: /fwvision/qcinspection/update_qc_order (Caused by NewConnectionError('<urllib3.connection.HTTPConnection object at 0xffffac63ba60>: Failed to establish a new connection: [Errno 111] Connection refused'))
2025-02-26 13:14:05,083 data_to_fw.py ERROR: Error : HTTPConnectionPool(host='127.0.0.1', port=7077): Max retries exceeded with url: /fwvision/qcinspection/update_qc_order (Caused by NewConnectionError('<urllib3.connection.HTTPConnection object at 0xffffac5aca90>: Failed to establish a new connection: [Errno 111] Connection refused'))
2025-02-26 13:14:08,789 data_to_fw.py ERROR: Error : HTTPConnectionPool(host='127.0.0.1', port=7077): Max retries exceeded with url: /fwvision/qcinspection/update_qc_order (Caused by NewConnectionError('<urllib3.connection.HTTPConnection object at 0xffffac6448e0>: Failed to establish a new connection: [Errno 111] Connection refused'))
2025-02-26 13:14:12,482 data_to_fw.py ERROR: Error : HTTPConnectionPool(host='127.0.0.1', port=7077): Max retries exceeded with url: /fwvision/qcinspection/update_qc_order (Caused by NewConnectionError('<urllib3.connection.HTTPConnection object at 0xffffac5c4ee0>: Failed to establish a new connection: [Errno 111] Connection refused'))
2025-02-26 13:14:16,186 data_to_fw.py ERROR: Error : HTTPConnectionPool(host='127.0.0.1', port=7077): Max retries exceeded with url: /fwvision/qcinspection/update_qc_order (Caused by NewConnectionError('<urllib3.connection.HTTPConnection object at 0xffffac63bb20>: Failed to establish a new connection: [Errno 111] Connection refused'))
2025-02-26 13:14:20,183 data_to_fw.py ERROR: Error : HTTPConnectionPool(host='127.0.0.1', port=7077): Max retries exceeded with url: /fwvision/qcinspection/update_qc_order (Caused by NewConnectionError('<urllib3.connection.HTTPConnection object at 0xffffac63bfa0>: Failed to establish a new connection: [Errno 111] Connection refused'))
2025-02-26 13:14:23,883 data_to_fw.py ERROR: Error : HTTPConnectionPool(host='127.0.0.1', port=7077): Max retries exceeded with url: /fwvision/qcinspection/update_qc_order (Caused by NewConnectionError('<urllib3.connection.HTTPConnection object at 0xffffac5ac7c0>: Failed to establish a new connection: [Errno 111] Connection refused'))
2025-02-26 13:14:27,583 data_to_fw.py ERROR: Error : HTTPConnectionPool(host='127.0.0.1', port=7077): Max retries exceeded with url: /fwvision/qcinspection/update_qc_order (Caused by NewConnectionError('<urllib3.connection.HTTPConnection object at 0xffffacee1ee0>: Failed to establish a new connection: [Errno 111] Connection refused'))
2025-02-26 13:14:31,275 data_to_fw.py ERROR: Error : HTTPConnectionPool(host='127.0.0.1', port=7077): Max retries exceeded with url: /fwvision/qcinspection/update_qc_order (Caused by NewConnectionError('<urllib3.connection.HTTPConnection object at 0xffffac617ca0>: Failed to establish a new connection: [Errno 111] Connection refused'))
2025-02-26 13:14:35,269 data_to_fw.py ERROR: Error : HTTPConnectionPool(host='127.0.0.1', port=7077): Max retries exceeded with url: /fwvision/qcinspection/update_qc_order (Caused by NewConnectionError('<urllib3.connection.HTTPConnection object at 0xffffacee1fd0>: Failed to establish a new connection: [Errno 111] Connection refused'))
2025-02-26 13:14:38,966 data_to_fw.py ERROR: Error : HTTPConnectionPool(host='127.0.0.1', port=7077): Max retries exceeded with url: /fwvision/qcinspection/update_qc_order (Caused by NewConnectionError('<urllib3.connection.HTTPConnection object at 0xffffac5ac7c0>: Failed to establish a new connection: [Errno 111] Connection refused'))
2025-02-26 13:14:42,658 data_to_fw.py ERROR: Error : HTTPConnectionPool(host='127.0.0.1', port=7077): Max retries exceeded with url: /fwvision/qcinspection/update_qc_order (Caused by NewConnectionError('<urllib3.connection.HTTPConnection object at 0xffffac63b400>: Failed to establish a new connection: [Errno 111] Connection refused'))
2025-02-26 13:14:46,355 data_to_fw.py ERROR: Error : HTTPConnectionPool(host='127.0.0.1', port=7077): Max retries exceeded with url: /fwvision/qcinspection/update_qc_order (Caused by NewConnectionError('<urllib3.connection.HTTPConnection object at 0xffffac63bf70>: Failed to establish a new connection: [Errno 111] Connection refused'))
2025-02-26 13:14:50,379 data_to_fw.py ERROR: Error : HTTPConnectionPool(host='127.0.0.1', port=7077): Max retries exceeded with url: /fwvision/qcinspection/update_qc_order (Caused by NewConnectionError('<urllib3.connection.HTTPConnection object at 0xffffac644970>: Failed to establish a new connection: [Errno 111] Connection refused'))
2025-02-26 13:14:54,076 data_to_fw.py ERROR: Error : HTTPConnectionPool(host='127.0.0.1', port=7077): Max retries exceeded with url: /fwvision/qcinspection/update_qc_order (Caused by NewConnectionError('<urllib3.connection.HTTPConnection object at 0xffffac5b9d90>: Failed to establish a new connection: [Errno 111] Connection refused'))
2025-02-26 13:14:57,788 data_to_fw.py ERROR: Error : HTTPConnectionPool(host='127.0.0.1', port=7077): Max retries exceeded with url: /fwvision/qcinspection/update_qc_order (Caused by NewConnectionError('<urllib3.connection.HTTPConnection object at 0xffffac5c4190>: Failed to establish a new connection: [Errno 111] Connection refused'))
2025-02-26 13:15:01,523 data_to_fw.py ERROR: Error : HTTPConnectionPool(host='127.0.0.1', port=7077): Max retries exceeded with url: /fwvision/qcinspection/update_qc_order (Caused by NewConnectionError('<urllib3.connection.HTTPConnection object at 0xffffac63bc10>: Failed to establish a new connection: [Errno 111] Connection refused'))
2025-02-26 13:15:05,523 data_to_fw.py ERROR: Error : HTTPConnectionPool(host='127.0.0.1', port=7077): Max retries exceeded with url: /fwvision/qcinspection/update_qc_order (Caused by NewConnectionError('<urllib3.connection.HTTPConnection object at 0xffffac644ee0>: Failed to establish a new connection: [Errno 111] Connection refused'))
2025-02-26 13:15:09,217 data_to_fw.py ERROR: Error : HTTPConnectionPool(host='127.0.0.1', port=7077): Max retries exceeded with url: /fwvision/qcinspection/update_qc_order (Caused by NewConnectionError('<urllib3.connection.HTTPConnection object at 0xffffacee1a00>: Failed to establish a new connection: [Errno 111] Connection refused'))
2025-02-26 13:15:12,921 data_to_fw.py ERROR: Error : HTTPConnectionPool(host='127.0.0.1', port=7077): Max retries exceeded with url: /fwvision/qcinspection/update_qc_order (Caused by NewConnectionError('<urllib3.connection.HTTPConnection object at 0xffffac5cd910>: Failed to establish a new connection: [Errno 111] Connection refused'))
2025-02-26 13:15:16,633 data_to_fw.py ERROR: Error : HTTPConnectionPool(host='127.0.0.1', port=7077): Max retries exceeded with url: /fwvision/qcinspection/update_qc_order (Caused by NewConnectionError('<urllib3.connection.HTTPConnection object at 0xffffac63b640>: Failed to establish a new connection: [Errno 111] Connection refused'))
2025-02-26 13:15:20,652 data_to_fw.py ERROR: Error : HTTPConnectionPool(host='127.0.0.1', port=7077): Max retries exceeded with url: /fwvision/qcinspection/update_qc_order (Caused by NewConnectionError('<urllib3.connection.HTTPConnection object at 0xffffac5c4a90>: Failed to establish a new connection: [Errno 111] Connection refused'))
2025-02-26 13:15:24,354 data_to_fw.py ERROR: Error : HTTPConnectionPool(host='127.0.0.1', port=7077): Max retries exceeded with url: /fwvision/qcinspection/update_qc_order (Caused by NewConnectionError('<urllib3.connection.HTTPConnection object at 0xffffac5aca90>: Failed to establish a new connection: [Errno 111] Connection refused'))
2025-02-26 13:15:28,060 data_to_fw.py ERROR: Error : HTTPConnectionPool(host='127.0.0.1', port=7077): Max retries exceeded with url: /fwvision/qcinspection/update_qc_order (Caused by NewConnectionError('<urllib3.connection.HTTPConnection object at 0xffffac644250>: Failed to establish a new connection: [Errno 111] Connection refused'))
2025-02-26 13:15:31,771 data_to_fw.py ERROR: Error : HTTPConnectionPool(host='127.0.0.1', port=7077): Max retries exceeded with url: /fwvision/qcinspection/update_qc_order (Caused by NewConnectionError('<urllib3.connection.HTTPConnection object at 0xffffac5cd190>: Failed to establish a new connection: [Errno 111] Connection refused'))
2025-02-26 13:15:35,767 data_to_fw.py ERROR: Error : HTTPConnectionPool(host='127.0.0.1', port=7077): Max retries exceeded with url: /fwvision/qcinspection/update_qc_order (Caused by NewConnectionError('<urllib3.connection.HTTPConnection object at 0xffffac63bd60>: Failed to establish a new connection: [Errno 111] Connection refused'))
2025-02-26 13:15:39,465 data_to_fw.py ERROR: Error : HTTPConnectionPool(host='127.0.0.1', port=7077): Max retries exceeded with url: /fwvision/qcinspection/update_qc_order (Caused by NewConnectionError('<urllib3.connection.HTTPConnection object at 0xffffac5c4c70>: Failed to establish a new connection: [Errno 111] Connection refused'))
2025-02-26 13:15:43,164 data_to_fw.py ERROR: Error : HTTPConnectionPool(host='127.0.0.1', port=7077): Max retries exceeded with url: /fwvision/qcinspection/update_qc_order (Caused by NewConnectionError('<urllib3.connection.HTTPConnection object at 0xffffac5ac190>: Failed to establish a new connection: [Errno 111] Connection refused'))
2025-02-26 13:15:46,857 data_to_fw.py ERROR: Error : HTTPConnectionPool(host='127.0.0.1', port=7077): Max retries exceeded with url: /fwvision/qcinspection/update_qc_order (Caused by NewConnectionError('<urllib3.connection.HTTPConnection object at 0xffffac5ac280>: Failed to establish a new connection: [Errno 111] Connection refused'))
2025-02-26 13:15:50,867 data_to_fw.py ERROR: Error : HTTPConnectionPool(host='127.0.0.1', port=7077): Max retries exceeded with url: /fwvision/qcinspection/update_qc_order (Caused by NewConnectionError('<urllib3.connection.HTTPConnection object at 0xffffac5b9640>: Failed to establish a new connection: [Errno 111] Connection refused'))
2025-02-26 13:15:54,574 data_to_fw.py ERROR: Error : HTTPConnectionPool(host='127.0.0.1', port=7077): Max retries exceeded with url: /fwvision/qcinspection/update_qc_order (Caused by NewConnectionError('<urllib3.connection.HTTPConnection object at 0xffffac5b90a0>: Failed to establish a new connection: [Errno 111] Connection refused'))
2025-02-26 13:15:58,262 data_to_fw.py ERROR: Error : HTTPConnectionPool(host='127.0.0.1', port=7077): Max retries exceeded with url: /fwvision/qcinspection/update_qc_order (Caused by NewConnectionError('<urllib3.connection.HTTPConnection object at 0xffffac5aceb0>: Failed to establish a new connection: [Errno 111] Connection refused'))
2025-02-26 13:16:01,957 data_to_fw.py ERROR: Error : HTTPConnectionPool(host='127.0.0.1', port=7077): Max retries exceeded with url: /fwvision/qcinspection/update_qc_order (Caused by NewConnectionError('<urllib3.connection.HTTPConnection object at 0xffffac5c4100>: Failed to establish a new connection: [Errno 111] Connection refused'))
2025-02-26 13:16:05,959 data_to_fw.py ERROR: Error : HTTPConnectionPool(host='127.0.0.1', port=7077): Max retries exceeded with url: /fwvision/qcinspection/update_qc_order (Caused by NewConnectionError('<urllib3.connection.HTTPConnection object at 0xffffac5c4970>: Failed to establish a new connection: [Errno 111] Connection refused'))
2025-02-26 13:16:09,671 data_to_fw.py ERROR: Error : HTTPConnectionPool(host='127.0.0.1', port=7077): Max retries exceeded with url: /fwvision/qcinspection/update_qc_order (Caused by NewConnectionError('<urllib3.connection.HTTPConnection object at 0xffffac63b2b0>: Failed to establish a new connection: [Errno 111] Connection refused'))
2025-02-26 13:16:13,382 data_to_fw.py ERROR: Error : HTTPConnectionPool(host='127.0.0.1', port=7077): Max retries exceeded with url: /fwvision/qcinspection/update_qc_order (Caused by NewConnectionError('<urllib3.connection.HTTPConnection object at 0xffffac617d90>: Failed to establish a new connection: [Errno 111] Connection refused'))
2025-02-26 13:16:17,072 data_to_fw.py ERROR: Error : HTTPConnectionPool(host='127.0.0.1', port=7077): Max retries exceeded with url: /fwvision/qcinspection/update_qc_order (Caused by NewConnectionError('<urllib3.connection.HTTPConnection object at 0xffffac63b820>: Failed to establish a new connection: [Errno 111] Connection refused'))
2025-02-26 13:16:21,078 data_to_fw.py ERROR: Error : HTTPConnectionPool(host='127.0.0.1', port=7077): Max retries exceeded with url: /fwvision/qcinspection/update_qc_order (Caused by NewConnectionError('<urllib3.connection.HTTPConnection object at 0xffffac5ac3d0>: Failed to establish a new connection: [Errno 111] Connection refused'))
2025-02-26 13:16:24,775 data_to_fw.py ERROR: Error : HTTPConnectionPool(host='127.0.0.1', port=7077): Max retries exceeded with url: /fwvision/qcinspection/update_qc_order (Caused by NewConnectionError('<urllib3.connection.HTTPConnection object at 0xffffac5c4340>: Failed to establish a new connection: [Errno 111] Connection refused'))
2025-02-26 13:16:28,477 data_to_fw.py ERROR: Error : HTTPConnectionPool(host='127.0.0.1', port=7077): Max retries exceeded with url: /fwvision/qcinspection/update_qc_order (Caused by NewConnectionError('<urllib3.connection.HTTPConnection object at 0xffffac5c4700>: Failed to establish a new connection: [Errno 111] Connection refused'))
2025-02-26 13:16:32,183 data_to_fw.py ERROR: Error : HTTPConnectionPool(host='127.0.0.1', port=7077): Max retries exceeded with url: /fwvision/qcinspection/update_qc_order (Caused by NewConnectionError('<urllib3.connection.HTTPConnection object at 0xffffac617100>: Failed to establish a new connection: [Errno 111] Connection refused'))
2025-02-26 13:16:36,188 data_to_fw.py ERROR: Error : HTTPConnectionPool(host='127.0.0.1', port=7077): Max retries exceeded with url: /fwvision/qcinspection/update_qc_order (Caused by NewConnectionError('<urllib3.connection.HTTPConnection object at 0xffffac617f10>: Failed to establish a new connection: [Errno 111] Connection refused'))
2025-02-26 13:16:39,887 data_to_fw.py ERROR: Error : HTTPConnectionPool(host='127.0.0.1', port=7077): Max retries exceeded with url: /fwvision/qcinspection/update_qc_order (Caused by NewConnectionError('<urllib3.connection.HTTPConnection object at 0xffffac5c4bb0>: Failed to establish a new connection: [Errno 111] Connection refused'))
2025-02-26 13:16:43,584 data_to_fw.py ERROR: Error : HTTPConnectionPool(host='127.0.0.1', port=7077): Max retries exceeded with url: /fwvision/qcinspection/update_qc_order (Caused by NewConnectionError('<urllib3.connection.HTTPConnection object at 0xffffac5acbb0>: Failed to establish a new connection: [Errno 111] Connection refused'))
2025-02-26 13:16:47,278 data_to_fw.py ERROR: Error : HTTPConnectionPool(host='127.0.0.1', port=7077): Max retries exceeded with url: /fwvision/qcinspection/update_qc_order (Caused by NewConnectionError('<urllib3.connection.HTTPConnection object at 0xffffac5ace80>: Failed to establish a new connection: [Errno 111] Connection refused'))
2025-02-26 13:16:51,278 data_to_fw.py ERROR: Error : HTTPConnectionPool(host='127.0.0.1', port=7077): Max retries exceeded with url: /fwvision/qcinspection/update_qc_order (Caused by NewConnectionError('<urllib3.connection.HTTPConnection object at 0xffffac63bee0>: Failed to establish a new connection: [Errno 111] Connection refused'))
2025-02-26 13:16:54,987 data_to_fw.py ERROR: Error : HTTPConnectionPool(host='127.0.0.1', port=7077): Max retries exceeded with url: /fwvision/qcinspection/update_qc_order (Caused by NewConnectionError('<urllib3.connection.HTTPConnection object at 0xffffac5b9ee0>: Failed to establish a new connection: [Errno 111] Connection refused'))
2025-02-26 13:16:58,689 data_to_fw.py ERROR: Error : HTTPConnectionPool(host='127.0.0.1', port=7077): Max retries exceeded with url: /fwvision/qcinspection/update_qc_order (Caused by NewConnectionError('<urllib3.connection.HTTPConnection object at 0xffffac63bb80>: Failed to establish a new connection: [Errno 111] Connection refused'))
2025-02-26 13:17:02,402 data_to_fw.py ERROR: Error : HTTPConnectionPool(host='127.0.0.1', port=7077): Max retries exceeded with url: /fwvision/qcinspection/update_qc_order (Caused by NewConnectionError('<urllib3.connection.HTTPConnection object at 0xffffac5acc10>: Failed to establish a new connection: [Errno 111] Connection refused'))
2025-02-26 13:17:06,406 data_to_fw.py ERROR: Error : HTTPConnectionPool(host='127.0.0.1', port=7077): Max retries exceeded with url: /fwvision/qcinspection/update_qc_order (Caused by NewConnectionError('<urllib3.connection.HTTPConnection object at 0xffffac5c46a0>: Failed to establish a new connection: [Errno 111] Connection refused'))
2025-02-26 13:17:10,112 data_to_fw.py ERROR: Error : HTTPConnectionPool(host='127.0.0.1', port=7077): Max retries exceeded with url: /fwvision/qcinspection/update_qc_order (Caused by NewConnectionError('<urllib3.connection.HTTPConnection object at 0xffffac5c42b0>: Failed to establish a new connection: [Errno 111] Connection refused'))
2025-02-26 13:17:13,812 data_to_fw.py ERROR: Error : HTTPConnectionPool(host='127.0.0.1', port=7077): Max retries exceeded with url: /fwvision/qcinspection/update_qc_order (Caused by NewConnectionError('<urllib3.connection.HTTPConnection object at 0xffffac5b9b80>: Failed to establish a new connection: [Errno 111] Connection refused'))
2025-02-26 13:17:17,528 data_to_fw.py ERROR: Error : HTTPConnectionPool(host='127.0.0.1', port=7077): Max retries exceeded with url: /fwvision/qcinspection/update_qc_order (Caused by NewConnectionError('<urllib3.connection.HTTPConnection object at 0xffffac5b9f40>: Failed to establish a new connection: [Errno 111] Connection refused'))
2025-02-26 13:17:21,526 data_to_fw.py ERROR: Error : HTTPConnectionPool(host='127.0.0.1', port=7077): Max retries exceeded with url: /fwvision/qcinspection/update_qc_order (Caused by NewConnectionError('<urllib3.connection.HTTPConnection object at 0xffffac5c48e0>: Failed to establish a new connection: [Errno 111] Connection refused'))
2025-02-26 13:17:25,222 data_to_fw.py ERROR: Error : HTTPConnectionPool(host='127.0.0.1', port=7077): Max retries exceeded with url: /fwvision/qcinspection/update_qc_order (Caused by NewConnectionError('<urllib3.connection.HTTPConnection object at 0xffffac5ac0d0>: Failed to establish a new connection: [Errno 111] Connection refused'))
2025-02-26 13:17:28,927 data_to_fw.py ERROR: Error : HTTPConnectionPool(host='127.0.0.1', port=7077): Max retries exceeded with url: /fwvision/qcinspection/update_qc_order (Caused by NewConnectionError('<urllib3.connection.HTTPConnection object at 0xffffac5acfa0>: Failed to establish a new connection: [Errno 111] Connection refused'))
2025-02-26 13:17:32,620 data_to_fw.py ERROR: Error : HTTPConnectionPool(host='127.0.0.1', port=7077): Max retries exceeded with url: /fwvision/qcinspection/update_qc_order (Caused by NewConnectionError('<urllib3.connection.HTTPConnection object at 0xffffac63bf10>: Failed to establish a new connection: [Errno 111] Connection refused'))
2025-02-26 13:17:36,622 data_to_fw.py ERROR: Error : HTTPConnectionPool(host='127.0.0.1', port=7077): Max retries exceeded with url: /fwvision/qcinspection/update_qc_order (Caused by NewConnectionError('<urllib3.connection.HTTPConnection object at 0xffffac617d00>: Failed to establish a new connection: [Errno 111] Connection refused'))
2025-02-26 13:17:40,327 data_to_fw.py ERROR: Error : HTTPConnectionPool(host='127.0.0.1', port=7077): Max retries exceeded with url: /fwvision/qcinspection/update_qc_order (Caused by NewConnectionError('<urllib3.connection.HTTPConnection object at 0xffffac63baf0>: Failed to establish a new connection: [Errno 111] Connection refused'))
2025-02-26 13:17:44,036 data_to_fw.py ERROR: Error : HTTPConnectionPool(host='127.0.0.1', port=7077): Max retries exceeded with url: /fwvision/qcinspection/update_qc_order (Caused by NewConnectionError('<urllib3.connection.HTTPConnection object at 0xffffac5c4040>: Failed to establish a new connection: [Errno 111] Connection refused'))
2025-02-26 13:17:47,748 data_to_fw.py ERROR: Error : HTTPConnectionPool(host='127.0.0.1', port=7077): Max retries exceeded with url: /fwvision/qcinspection/update_qc_order (Caused by NewConnectionError('<urllib3.connection.HTTPConnection object at 0xffffac5c46d0>: Failed to establish a new connection: [Errno 111] Connection refused'))
2025-02-26 13:17:51,761 data_to_fw.py ERROR: Error : HTTPConnectionPool(host='127.0.0.1', port=7077): Max retries exceeded with url: /fwvision/qcinspection/update_qc_order (Caused by NewConnectionError('<urllib3.connection.HTTPConnection object at 0xffffac5acfd0>: Failed to establish a new connection: [Errno 111] Connection refused'))
2025-02-26 13:17:55,467 data_to_fw.py ERROR: Error : HTTPConnectionPool(host='127.0.0.1', port=7077): Max retries exceeded with url: /fwvision/qcinspection/update_qc_order (Caused by NewConnectionError('<urllib3.connection.HTTPConnection object at 0xffffac617d90>: Failed to establish a new connection: [Errno 111] Connection refused'))
2025-02-26 13:17:59,186 data_to_fw.py ERROR: Error : HTTPConnectionPool(host='127.0.0.1', port=7077): Max retries exceeded with url: /fwvision/qcinspection/update_qc_order (Caused by NewConnectionError('<urllib3.connection.HTTPConnection object at 0xffffac617c10>: Failed to establish a new connection: [Errno 111] Connection refused'))
2025-02-26 13:18:02,875 data_to_fw.py ERROR: Error : HTTPConnectionPool(host='127.0.0.1', port=7077): Max retries exceeded with url: /fwvision/qcinspection/update_qc_order (Caused by NewConnectionError('<urllib3.connection.HTTPConnection object at 0xffffac5ac400>: Failed to establish a new connection: [Errno 111] Connection refused'))
2025-02-26 13:18:06,867 data_to_fw.py ERROR: Error : HTTPConnectionPool(host='127.0.0.1', port=7077): Max retries exceeded with url: /fwvision/qcinspection/update_qc_order (Caused by NewConnectionError('<urllib3.connection.HTTPConnection object at 0xffffac5c4130>: Failed to establish a new connection: [Errno 111] Connection refused'))
2025-02-26 13:18:10,564 data_to_fw.py ERROR: Error : HTTPConnectionPool(host='127.0.0.1', port=7077): Max retries exceeded with url: /fwvision/qcinspection/update_qc_order (Caused by NewConnectionError('<urllib3.connection.HTTPConnection object at 0xffffac5c44c0>: Failed to establish a new connection: [Errno 111] Connection refused'))
2025-02-26 13:18:14,267 data_to_fw.py ERROR: Error : HTTPConnectionPool(host='127.0.0.1', port=7077): Max retries exceeded with url: /fwvision/qcinspection/update_qc_order (Caused by NewConnectionError('<urllib3.connection.HTTPConnection object at 0xffffac63b880>: Failed to establish a new connection: [Errno 111] Connection refused'))
2025-02-26 13:18:17,963 data_to_fw.py ERROR: Error : HTTPConnectionPool(host='127.0.0.1', port=7077): Max retries exceeded with url: /fwvision/qcinspection/update_qc_order (Caused by NewConnectionError('<urllib3.connection.HTTPConnection object at 0xffffac5b95e0>: Failed to establish a new connection: [Errno 111] Connection refused'))
2025-02-26 13:18:21,974 data_to_fw.py ERROR: Error : HTTPConnectionPool(host='127.0.0.1', port=7077): Max retries exceeded with url: /fwvision/qcinspection/update_qc_order (Caused by NewConnectionError('<urllib3.connection.HTTPConnection object at 0xffffac63baf0>: Failed to establish a new connection: [Errno 111] Connection refused'))
2025-02-26 13:18:25,674 data_to_fw.py ERROR: Error : HTTPConnectionPool(host='127.0.0.1', port=7077): Max retries exceeded with url: /fwvision/qcinspection/update_qc_order (Caused by NewConnectionError('<urllib3.connection.HTTPConnection object at 0xffffac5c4820>: Failed to establish a new connection: [Errno 111] Connection refused'))
2025-02-26 13:18:29,368 data_to_fw.py ERROR: Error : HTTPConnectionPool(host='127.0.0.1', port=7077): Max retries exceeded with url: /fwvision/qcinspection/update_qc_order (Caused by NewConnectionError('<urllib3.connection.HTTPConnection object at 0xffffac5ac3d0>: Failed to establish a new connection: [Errno 111] Connection refused'))
2025-02-26 13:18:33,060 data_to_fw.py ERROR: Error : HTTPConnectionPool(host='127.0.0.1', port=7077): Max retries exceeded with url: /fwvision/qcinspection/update_qc_order (Caused by NewConnectionError('<urllib3.connection.HTTPConnection object at 0xffffac5ac4c0>: Failed to establish a new connection: [Errno 111] Connection refused'))
2025-02-26 13:18:37,067 data_to_fw.py ERROR: Error : HTTPConnectionPool(host='127.0.0.1', port=7077): Max retries exceeded with url: /fwvision/qcinspection/update_qc_order (Caused by NewConnectionError('<urllib3.connection.HTTPConnection object at 0xffffac5b9f10>: Failed to establish a new connection: [Errno 111] Connection refused'))
2025-02-26 13:18:40,765 data_to_fw.py ERROR: Error : HTTPConnectionPool(host='127.0.0.1', port=7077): Max retries exceeded with url: /fwvision/qcinspection/update_qc_order (Caused by NewConnectionError('<urllib3.connection.HTTPConnection object at 0xffffac5b9430>: Failed to establish a new connection: [Errno 111] Connection refused'))
2025-02-26 13:18:44,459 data_to_fw.py ERROR: Error : HTTPConnectionPool(host='127.0.0.1', port=7077): Max retries exceeded with url: /fwvision/qcinspection/update_qc_order (Caused by NewConnectionError('<urllib3.connection.HTTPConnection object at 0xffffac5ac160>: Failed to establish a new connection: [Errno 111] Connection refused'))
2025-02-26 13:18:48,168 data_to_fw.py ERROR: Error : HTTPConnectionPool(host='127.0.0.1', port=7077): Max retries exceeded with url: /fwvision/qcinspection/update_qc_order (Caused by NewConnectionError('<urllib3.connection.HTTPConnection object at 0xffffac5c4220>: Failed to establish a new connection: [Errno 111] Connection refused'))
2025-02-26 13:18:52,166 data_to_fw.py ERROR: Error : HTTPConnectionPool(host='127.0.0.1', port=7077): Max retries exceeded with url: /fwvision/qcinspection/update_qc_order (Caused by NewConnectionError('<urllib3.connection.HTTPConnection object at 0xffffac5c4d30>: Failed to establish a new connection: [Errno 111] Connection refused'))
2025-02-26 13:18:55,870 data_to_fw.py ERROR: Error : HTTPConnectionPool(host='127.0.0.1', port=7077): Max retries exceeded with url: /fwvision/qcinspection/update_qc_order (Caused by NewConnectionError('<urllib3.connection.HTTPConnection object at 0xffffac63b610>: Failed to establish a new connection: [Errno 111] Connection refused'))
2025-02-26 13:18:59,592 data_to_fw.py ERROR: Error : HTTPConnectionPool(host='127.0.0.1', port=7077): Max retries exceeded with url: /fwvision/qcinspection/update_qc_order (Caused by NewConnectionError('<urllib3.connection.HTTPConnection object at 0xffffac617070>: Failed to establish a new connection: [Errno 111] Connection refused'))
2025-02-26 13:19:03,302 data_to_fw.py ERROR: Error : HTTPConnectionPool(host='127.0.0.1', port=7077): Max retries exceeded with url: /fwvision/qcinspection/update_qc_order (Caused by NewConnectionError('<urllib3.connection.HTTPConnection object at 0xffffac63b7f0>: Failed to establish a new connection: [Errno 111] Connection refused'))
2025-02-26 13:19:07,314 data_to_fw.py ERROR: Error : HTTPConnectionPool(host='127.0.0.1', port=7077): Max retries exceeded with url: /fwvision/qcinspection/update_qc_order (Caused by NewConnectionError('<urllib3.connection.HTTPConnection object at 0xffffac5ac190>: Failed to establish a new connection: [Errno 111] Connection refused'))
2025-02-26 13:19:11,018 data_to_fw.py ERROR: Error : HTTPConnectionPool(host='127.0.0.1', port=7077): Max retries exceeded with url: /fwvision/qcinspection/update_qc_order (Caused by NewConnectionError('<urllib3.connection.HTTPConnection object at 0xffffac5c4d00>: Failed to establish a new connection: [Errno 111] Connection refused'))
2025-02-26 13:19:14,712 data_to_fw.py ERROR: Error : HTTPConnectionPool(host='127.0.0.1', port=7077): Max retries exceeded with url: /fwvision/qcinspection/update_qc_order (Caused by NewConnectionError('<urllib3.connection.HTTPConnection object at 0xffffac5c4130>: Failed to establish a new connection: [Errno 111] Connection refused'))
2025-02-26 13:19:18,406 data_to_fw.py ERROR: Error : HTTPConnectionPool(host='127.0.0.1', port=7077): Max retries exceeded with url: /fwvision/qcinspection/update_qc_order (Caused by NewConnectionError('<urllib3.connection.HTTPConnection object at 0xffffac617c70>: Failed to establish a new connection: [Errno 111] Connection refused'))
2025-02-26 13:19:22,411 data_to_fw.py ERROR: Error : HTTPConnectionPool(host='127.0.0.1', port=7077): Max retries exceeded with url: /fwvision/qcinspection/update_qc_order (Caused by NewConnectionError('<urllib3.connection.HTTPConnection object at 0xffffac617f10>: Failed to establish a new connection: [Errno 111] Connection refused'))
2025-02-26 13:19:26,117 data_to_fw.py ERROR: Error : HTTPConnectionPool(host='127.0.0.1', port=7077): Max retries exceeded with url: /fwvision/qcinspection/update_qc_order (Caused by NewConnectionError('<urllib3.connection.HTTPConnection object at 0xffffac5c4340>: Failed to establish a new connection: [Errno 111] Connection refused'))
2025-02-26 13:19:29,822 data_to_fw.py ERROR: Error : HTTPConnectionPool(host='127.0.0.1', port=7077): Max retries exceeded with url: /fwvision/qcinspection/update_qc_order (Caused by NewConnectionError('<urllib3.connection.HTTPConnection object at 0xffffac5ac2e0>: Failed to establish a new connection: [Errno 111] Connection refused'))
2025-02-26 13:19:33,526 data_to_fw.py ERROR: Error : HTTPConnectionPool(host='127.0.0.1', port=7077): Max retries exceeded with url: /fwvision/qcinspection/update_qc_order (Caused by NewConnectionError('<urllib3.connection.HTTPConnection object at 0xffffac5acf70>: Failed to establish a new connection: [Errno 111] Connection refused'))
2025-02-26 13:19:37,522 data_to_fw.py ERROR: Error : HTTPConnectionPool(host='127.0.0.1', port=7077): Max retries exceeded with url: /fwvision/qcinspection/update_qc_order (Caused by NewConnectionError('<urllib3.connection.HTTPConnection object at 0xffffac63bdc0>: Failed to establish a new connection: [Errno 111] Connection refused'))
2025-02-26 13:19:41,217 data_to_fw.py ERROR: Error : HTTPConnectionPool(host='127.0.0.1', port=7077): Max retries exceeded with url: /fwvision/qcinspection/update_qc_order (Caused by NewConnectionError('<urllib3.connection.HTTPConnection object at 0xffffac5b9190>: Failed to establish a new connection: [Errno 111] Connection refused'))
2025-02-26 13:19:44,909 data_to_fw.py ERROR: Error : HTTPConnectionPool(host='127.0.0.1', port=7077): Max retries exceeded with url: /fwvision/qcinspection/update_qc_order (Caused by NewConnectionError('<urllib3.connection.HTTPConnection object at 0xffffac63bb80>: Failed to establish a new connection: [Errno 111] Connection refused'))
2025-02-26 13:19:48,604 data_to_fw.py ERROR: Error : HTTPConnectionPool(host='127.0.0.1', port=7077): Max retries exceeded with url: /fwvision/qcinspection/update_qc_order (Caused by NewConnectionError('<urllib3.connection.HTTPConnection object at 0xffffac5c46a0>: Failed to establish a new connection: [Errno 111] Connection refused'))
2025-02-26 13:19:52,758 data_to_fw.py ERROR: Error : HTTPConnectionPool(host='127.0.0.1', port=7077): Max retries exceeded with url: /fwvision/qcinspection/update_qc_order (Caused by NewConnectionError('<urllib3.connection.HTTPConnection object at 0xffffac5c4d60>: Failed to establish a new connection: [Errno 111] Connection refused'))
2025-02-26 13:19:56,459 data_to_fw.py ERROR: Error : HTTPConnectionPool(host='127.0.0.1', port=7077): Max retries exceeded with url: /fwvision/qcinspection/update_qc_order (Caused by NewConnectionError('<urllib3.connection.HTTPConnection object at 0xffffac5b9460>: Failed to establish a new connection: [Errno 111] Connection refused'))
2025-02-26 13:20:00,139 data_to_fw.py ERROR: Error : HTTPConnectionPool(host='127.0.0.1', port=7077): Max retries exceeded with url: /fwvision/qcinspection/update_qc_order (Caused by NewConnectionError('<urllib3.connection.HTTPConnection object at 0xffffac5acbe0>: Failed to establish a new connection: [Errno 111] Connection refused'))
2025-02-26 13:20:03,846 data_to_fw.py ERROR: Error : HTTPConnectionPool(host='127.0.0.1', port=7077): Max retries exceeded with url: /fwvision/qcinspection/update_qc_order (Caused by NewConnectionError('<urllib3.connection.HTTPConnection object at 0xffffac5b9490>: Failed to establish a new connection: [Errno 111] Connection refused'))
2025-02-26 13:20:07,864 data_to_fw.py ERROR: Error : HTTPConnectionPool(host='127.0.0.1', port=7077): Max retries exceeded with url: /fwvision/qcinspection/update_qc_order (Caused by NewConnectionError('<urllib3.connection.HTTPConnection object at 0xffffac617bb0>: Failed to establish a new connection: [Errno 111] Connection refused'))
2025-02-26 13:20:11,570 data_to_fw.py ERROR: Error : HTTPConnectionPool(host='127.0.0.1', port=7077): Max retries exceeded with url: /fwvision/qcinspection/update_qc_order (Caused by NewConnectionError('<urllib3.connection.HTTPConnection object at 0xffffac5c4f70>: Failed to establish a new connection: [Errno 111] Connection refused'))
2025-02-26 13:20:15,284 data_to_fw.py ERROR: Error : HTTPConnectionPool(host='127.0.0.1', port=7077): Max retries exceeded with url: /fwvision/qcinspection/update_qc_order (Caused by NewConnectionError('<urllib3.connection.HTTPConnection object at 0xffffac63b2e0>: Failed to establish a new connection: [Errno 111] Connection refused'))
2025-02-26 13:20:18,983 data_to_fw.py ERROR: Error : HTTPConnectionPool(host='127.0.0.1', port=7077): Max retries exceeded with url: /fwvision/qcinspection/update_qc_order (Caused by NewConnectionError('<urllib3.connection.HTTPConnection object at 0xffffac63b2b0>: Failed to establish a new connection: [Errno 111] Connection refused'))
2025-02-26 13:20:22,984 data_to_fw.py ERROR: Error : HTTPConnectionPool(host='127.0.0.1', port=7077): Max retries exceeded with url: /fwvision/qcinspection/update_qc_order (Caused by NewConnectionError('<urllib3.connection.HTTPConnection object at 0xffffac5ac9d0>: Failed to establish a new connection: [Errno 111] Connection refused'))
2025-02-26 13:20:26,680 data_to_fw.py ERROR: Error : HTTPConnectionPool(host='127.0.0.1', port=7077): Max retries exceeded with url: /fwvision/qcinspection/update_qc_order (Caused by NewConnectionError('<urllib3.connection.HTTPConnection object at 0xffffac63b250>: Failed to establish a new connection: [Errno 111] Connection refused'))
2025-02-26 13:20:30,390 data_to_fw.py ERROR: Error : HTTPConnectionPool(host='127.0.0.1', port=7077): Max retries exceeded with url: /fwvision/qcinspection/update_qc_order (Caused by NewConnectionError('<urllib3.connection.HTTPConnection object at 0xffffac5c48b0>: Failed to establish a new connection: [Errno 111] Connection refused'))
2025-02-26 13:20:34,102 data_to_fw.py ERROR: Error : HTTPConnectionPool(host='127.0.0.1', port=7077): Max retries exceeded with url: /fwvision/qcinspection/update_qc_order (Caused by NewConnectionError('<urllib3.connection.HTTPConnection object at 0xffffac5c4970>: Failed to establish a new connection: [Errno 111] Connection refused'))
2025-02-26 13:20:38,120 data_to_fw.py ERROR: Error : HTTPConnectionPool(host='127.0.0.1', port=7077): Max retries exceeded with url: /fwvision/qcinspection/update_qc_order (Caused by NewConnectionError('<urllib3.connection.HTTPConnection object at 0xffffac5ac1c0>: Failed to establish a new connection: [Errno 111] Connection refused'))
2025-02-26 13:20:41,827 data_to_fw.py ERROR: Error : HTTPConnectionPool(host='127.0.0.1', port=7077): Max retries exceeded with url: /fwvision/qcinspection/update_qc_order (Caused by NewConnectionError('<urllib3.connection.HTTPConnection object at 0xffffac5ac970>: Failed to establish a new connection: [Errno 111] Connection refused'))
2025-02-26 13:20:45,528 data_to_fw.py ERROR: Error : HTTPConnectionPool(host='127.0.0.1', port=7077): Max retries exceeded with url: /fwvision/qcinspection/update_qc_order (Caused by NewConnectionError('<urllib3.connection.HTTPConnection object at 0xffffac5ac0d0>: Failed to establish a new connection: [Errno 111] Connection refused'))
2025-02-26 13:20:49,218 data_to_fw.py ERROR: Error : HTTPConnectionPool(host='127.0.0.1', port=7077): Max retries exceeded with url: /fwvision/qcinspection/update_qc_order (Caused by NewConnectionError('<urllib3.connection.HTTPConnection object at 0xffffac5ac910>: Failed to establish a new connection: [Errno 111] Connection refused'))
2025-02-26 13:20:53,212 data_to_fw.py ERROR: Error : HTTPConnectionPool(host='127.0.0.1', port=7077): Max retries exceeded with url: /fwvision/qcinspection/update_qc_order (Caused by NewConnectionError('<urllib3.connection.HTTPConnection object at 0xffffac5c47c0>: Failed to establish a new connection: [Errno 111] Connection refused'))
2025-02-26 13:20:56,911 data_to_fw.py ERROR: Error : HTTPConnectionPool(host='127.0.0.1', port=7077): Max retries exceeded with url: /fwvision/qcinspection/update_qc_order (Caused by NewConnectionError('<urllib3.connection.HTTPConnection object at 0xffffac5c44c0>: Failed to establish a new connection: [Errno 111] Connection refused'))
2025-02-26 13:21:00,621 data_to_fw.py ERROR: Error : HTTPConnectionPool(host='127.0.0.1', port=7077): Max retries exceeded with url: /fwvision/qcinspection/update_qc_order (Caused by NewConnectionError('<urllib3.connection.HTTPConnection object at 0xffffac63b7c0>: Failed to establish a new connection: [Errno 111] Connection refused'))
2025-02-26 13:21:04,319 data_to_fw.py ERROR: Error : HTTPConnectionPool(host='127.0.0.1', port=7077): Max retries exceeded with url: /fwvision/qcinspection/update_qc_order (Caused by NewConnectionError('<urllib3.connection.HTTPConnection object at 0xffffac5b9250>: Failed to establish a new connection: [Errno 111] Connection refused'))
2025-02-26 13:21:08,304 data_to_fw.py ERROR: Error : HTTPConnectionPool(host='127.0.0.1', port=7077): Max retries exceeded with url: /fwvision/qcinspection/update_qc_order (Caused by NewConnectionError('<urllib3.connection.HTTPConnection object at 0xffffac5c4eb0>: Failed to establish a new connection: [Errno 111] Connection refused'))
2025-02-26 13:21:11,992 data_to_fw.py ERROR: Error : HTTPConnectionPool(host='127.0.0.1', port=7077): Max retries exceeded with url: /fwvision/qcinspection/update_qc_order (Caused by NewConnectionError('<urllib3.connection.HTTPConnection object at 0xffffac63b760>: Failed to establish a new connection: [Errno 111] Connection refused'))
2025-02-26 13:21:15,688 data_to_fw.py ERROR: Error : HTTPConnectionPool(host='127.0.0.1', port=7077): Max retries exceeded with url: /fwvision/qcinspection/update_qc_order (Caused by NewConnectionError('<urllib3.connection.HTTPConnection object at 0xffffac63bb50>: Failed to establish a new connection: [Errno 111] Connection refused'))
2025-02-26 13:21:19,389 data_to_fw.py ERROR: Error : HTTPConnectionPool(host='127.0.0.1', port=7077): Max retries exceeded with url: /fwvision/qcinspection/update_qc_order (Caused by NewConnectionError('<urllib3.connection.HTTPConnection object at 0xffffac5b9c10>: Failed to establish a new connection: [Errno 111] Connection refused'))
2025-02-26 13:21:23,404 data_to_fw.py ERROR: Error : HTTPConnectionPool(host='127.0.0.1', port=7077): Max retries exceeded with url: /fwvision/qcinspection/update_qc_order (Caused by NewConnectionError('<urllib3.connection.HTTPConnection object at 0xffffac5ac700>: Failed to establish a new connection: [Errno 111] Connection refused'))
2025-02-26 13:21:27,126 data_to_fw.py ERROR: Error : HTTPConnectionPool(host='127.0.0.1', port=7077): Max retries exceeded with url: /fwvision/qcinspection/update_qc_order (Caused by NewConnectionError('<urllib3.connection.HTTPConnection object at 0xffffac5b95e0>: Failed to establish a new connection: [Errno 111] Connection refused'))
2025-02-26 13:21:30,839 data_to_fw.py ERROR: Error : HTTPConnectionPool(host='127.0.0.1', port=7077): Max retries exceeded with url: /fwvision/qcinspection/update_qc_order (Caused by NewConnectionError('<urllib3.connection.HTTPConnection object at 0xffffac63be20>: Failed to establish a new connection: [Errno 111] Connection refused'))
2025-02-26 13:21:34,548 data_to_fw.py ERROR: Error : HTTPConnectionPool(host='127.0.0.1', port=7077): Max retries exceeded with url: /fwvision/qcinspection/update_qc_order (Caused by NewConnectionError('<urllib3.connection.HTTPConnection object at 0xffffac63b550>: Failed to establish a new connection: [Errno 111] Connection refused'))
2025-02-26 13:21:38,556 data_to_fw.py ERROR: Error : HTTPConnectionPool(host='127.0.0.1', port=7077): Max retries exceeded with url: /fwvision/qcinspection/update_qc_order (Caused by NewConnectionError('<urllib3.connection.HTTPConnection object at 0xffffac5c4760>: Failed to establish a new connection: [Errno 111] Connection refused'))
2025-02-26 13:21:42,249 data_to_fw.py ERROR: Error : HTTPConnectionPool(host='127.0.0.1', port=7077): Max retries exceeded with url: /fwvision/qcinspection/update_qc_order (Caused by NewConnectionError('<urllib3.connection.HTTPConnection object at 0xffffac5c44c0>: Failed to establish a new connection: [Errno 111] Connection refused'))
2025-02-26 13:21:45,947 data_to_fw.py ERROR: Error : HTTPConnectionPool(host='127.0.0.1', port=7077): Max retries exceeded with url: /fwvision/qcinspection/update_qc_order (Caused by NewConnectionError('<urllib3.connection.HTTPConnection object at 0xffffac5acac0>: Failed to establish a new connection: [Errno 111] Connection refused'))
2025-02-26 13:21:49,647 data_to_fw.py ERROR: Error : HTTPConnectionPool(host='127.0.0.1', port=7077): Max retries exceeded with url: /fwvision/qcinspection/update_qc_order (Caused by NewConnectionError('<urllib3.connection.HTTPConnection object at 0xffffac63b610>: Failed to establish a new connection: [Errno 111] Connection refused'))
2025-02-26 13:21:53,645 data_to_fw.py ERROR: Error : HTTPConnectionPool(host='127.0.0.1', port=7077): Max retries exceeded with url: /fwvision/qcinspection/update_qc_order (Caused by NewConnectionError('<urllib3.connection.HTTPConnection object at 0xffffac5c4cd0>: Failed to establish a new connection: [Errno 111] Connection refused'))
2025-02-26 13:21:57,340 data_to_fw.py ERROR: Error : HTTPConnectionPool(host='127.0.0.1', port=7077): Max retries exceeded with url: /fwvision/qcinspection/update_qc_order (Caused by NewConnectionError('<urllib3.connection.HTTPConnection object at 0xffffac5c49a0>: Failed to establish a new connection: [Errno 111] Connection refused'))
2025-02-26 13:22:01,036 data_to_fw.py ERROR: Error : HTTPConnectionPool(host='127.0.0.1', port=7077): Max retries exceeded with url: /fwvision/qcinspection/update_qc_order (Caused by NewConnectionError('<urllib3.connection.HTTPConnection object at 0xffffac5acd60>: Failed to establish a new connection: [Errno 111] Connection refused'))
2025-02-26 13:22:04,736 data_to_fw.py ERROR: Error : HTTPConnectionPool(host='127.0.0.1', port=7077): Max retries exceeded with url: /fwvision/qcinspection/update_qc_order (Caused by NewConnectionError('<urllib3.connection.HTTPConnection object at 0xffffac5acb80>: Failed to establish a new connection: [Errno 111] Connection refused'))
2025-02-26 13:22:08,728 data_to_fw.py ERROR: Error : HTTPConnectionPool(host='127.0.0.1', port=7077): Max retries exceeded with url: /fwvision/qcinspection/update_qc_order (Caused by NewConnectionError('<urllib3.connection.HTTPConnection object at 0xffffac5acbe0>: Failed to establish a new connection: [Errno 111] Connection refused'))
2025-02-26 13:22:12,408 data_to_fw.py ERROR: Error : HTTPConnectionPool(host='127.0.0.1', port=7077): Max retries exceeded with url: /fwvision/qcinspection/update_qc_order (Caused by NewConnectionError('<urllib3.connection.HTTPConnection object at 0xffffac5acdc0>: Failed to establish a new connection: [Errno 111] Connection refused'))
2025-02-26 13:22:16,105 data_to_fw.py ERROR: Error : HTTPConnectionPool(host='127.0.0.1', port=7077): Max retries exceeded with url: /fwvision/qcinspection/update_qc_order (Caused by NewConnectionError('<urllib3.connection.HTTPConnection object at 0xffffac5c4550>: Failed to establish a new connection: [Errno 111] Connection refused'))
2025-02-26 13:22:19,809 data_to_fw.py ERROR: Error : HTTPConnectionPool(host='127.0.0.1', port=7077): Max retries exceeded with url: /fwvision/qcinspection/update_qc_order (Caused by NewConnectionError('<urllib3.connection.HTTPConnection object at 0xffffac63b6d0>: Failed to establish a new connection: [Errno 111] Connection refused'))
2025-02-26 13:22:23,802 data_to_fw.py ERROR: Error : HTTPConnectionPool(host='127.0.0.1', port=7077): Max retries exceeded with url: /fwvision/qcinspection/update_qc_order (Caused by NewConnectionError('<urllib3.connection.HTTPConnection object at 0xffffac63bf70>: Failed to establish a new connection: [Errno 111] Connection refused'))
2025-02-26 13:22:27,489 data_to_fw.py ERROR: Error : HTTPConnectionPool(host='127.0.0.1', port=7077): Max retries exceeded with url: /fwvision/qcinspection/update_qc_order (Caused by NewConnectionError('<urllib3.connection.HTTPConnection object at 0xffffac5b9610>: Failed to establish a new connection: [Errno 111] Connection refused'))
2025-02-26 13:22:31,194 data_to_fw.py ERROR: Error : HTTPConnectionPool(host='127.0.0.1', port=7077): Max retries exceeded with url: /fwvision/qcinspection/update_qc_order (Caused by NewConnectionError('<urllib3.connection.HTTPConnection object at 0xffffac5c4850>: Failed to establish a new connection: [Errno 111] Connection refused'))
2025-02-26 13:22:34,910 data_to_fw.py ERROR: Error : HTTPConnectionPool(host='127.0.0.1', port=7077): Max retries exceeded with url: /fwvision/qcinspection/update_qc_order (Caused by NewConnectionError('<urllib3.connection.HTTPConnection object at 0xffffac63b1f0>: Failed to establish a new connection: [Errno 111] Connection refused'))
2025-02-26 13:22:38,917 data_to_fw.py ERROR: Error : HTTPConnectionPool(host='127.0.0.1', port=7077): Max retries exceeded with url: /fwvision/qcinspection/update_qc_order (Caused by NewConnectionError('<urllib3.connection.HTTPConnection object at 0xffffac63b100>: Failed to establish a new connection: [Errno 111] Connection refused'))
2025-02-26 13:22:42,613 data_to_fw.py ERROR: Error : HTTPConnectionPool(host='127.0.0.1', port=7077): Max retries exceeded with url: /fwvision/qcinspection/update_qc_order (Caused by NewConnectionError('<urllib3.connection.HTTPConnection object at 0xffffac5b94c0>: Failed to establish a new connection: [Errno 111] Connection refused'))
2025-02-26 13:22:46,311 data_to_fw.py ERROR: Error : HTTPConnectionPool(host='127.0.0.1', port=7077): Max retries exceeded with url: /fwvision/qcinspection/update_qc_order (Caused by NewConnectionError('<urllib3.connection.HTTPConnection object at 0xffffac5ac550>: Failed to establish a new connection: [Errno 111] Connection refused'))
2025-02-26 13:22:50,011 data_to_fw.py ERROR: Error : HTTPConnectionPool(host='127.0.0.1', port=7077): Max retries exceeded with url: /fwvision/qcinspection/update_qc_order (Caused by NewConnectionError('<urllib3.connection.HTTPConnection object at 0xffffac5b9fa0>: Failed to establish a new connection: [Errno 111] Connection refused'))
2025-02-26 13:22:54,011 data_to_fw.py ERROR: Error : HTTPConnectionPool(host='127.0.0.1', port=7077): Max retries exceeded with url: /fwvision/qcinspection/update_qc_order (Caused by NewConnectionError('<urllib3.connection.HTTPConnection object at 0xffffac63bb80>: Failed to establish a new connection: [Errno 111] Connection refused'))
2025-02-26 13:22:57,707 data_to_fw.py ERROR: Error : HTTPConnectionPool(host='127.0.0.1', port=7077): Max retries exceeded with url: /fwvision/qcinspection/update_qc_order (Caused by NewConnectionError('<urllib3.connection.HTTPConnection object at 0xffffac63b1f0>: Failed to establish a new connection: [Errno 111] Connection refused'))
2025-02-26 13:23:01,409 data_to_fw.py ERROR: Error : HTTPConnectionPool(host='127.0.0.1', port=7077): Max retries exceeded with url: /fwvision/qcinspection/update_qc_order (Caused by NewConnectionError('<urllib3.connection.HTTPConnection object at 0xffffac5c4070>: Failed to establish a new connection: [Errno 111] Connection refused'))
2025-02-26 13:23:05,112 data_to_fw.py ERROR: Error : HTTPConnectionPool(host='127.0.0.1', port=7077): Max retries exceeded with url: /fwvision/qcinspection/update_qc_order (Caused by NewConnectionError('<urllib3.connection.HTTPConnection object at 0xffffac617c10>: Failed to establish a new connection: [Errno 111] Connection refused'))
2025-02-26 13:23:09,106 data_to_fw.py ERROR: Error : HTTPConnectionPool(host='127.0.0.1', port=7077): Max retries exceeded with url: /fwvision/qcinspection/update_qc_order (Caused by NewConnectionError('<urllib3.connection.HTTPConnection object at 0xffffac5aca30>: Failed to establish a new connection: [Errno 111] Connection refused'))
2025-02-26 13:23:12,821 data_to_fw.py ERROR: Error : HTTPConnectionPool(host='127.0.0.1', port=7077): Max retries exceeded with url: /fwvision/qcinspection/update_qc_order (Caused by NewConnectionError('<urllib3.connection.HTTPConnection object at 0xffffac63ba30>: Failed to establish a new connection: [Errno 111] Connection refused'))
2025-02-26 13:23:16,533 data_to_fw.py ERROR: Error : HTTPConnectionPool(host='127.0.0.1', port=7077): Max retries exceeded with url: /fwvision/qcinspection/update_qc_order (Caused by NewConnectionError('<urllib3.connection.HTTPConnection object at 0xffffac5c4be0>: Failed to establish a new connection: [Errno 111] Connection refused'))
2025-02-26 13:23:20,234 data_to_fw.py ERROR: Error : HTTPConnectionPool(host='127.0.0.1', port=7077): Max retries exceeded with url: /fwvision/qcinspection/update_qc_order (Caused by NewConnectionError('<urllib3.connection.HTTPConnection object at 0xffffac5c4520>: Failed to establish a new connection: [Errno 111] Connection refused'))
2025-02-26 13:23:24,232 data_to_fw.py ERROR: Error : HTTPConnectionPool(host='127.0.0.1', port=7077): Max retries exceeded with url: /fwvision/qcinspection/update_qc_order (Caused by NewConnectionError('<urllib3.connection.HTTPConnection object at 0xffffac5acaf0>: Failed to establish a new connection: [Errno 111] Connection refused'))
2025-02-26 13:23:27,925 data_to_fw.py ERROR: Error : HTTPConnectionPool(host='127.0.0.1', port=7077): Max retries exceeded with url: /fwvision/qcinspection/update_qc_order (Caused by NewConnectionError('<urllib3.connection.HTTPConnection object at 0xffffac5b9c70>: Failed to establish a new connection: [Errno 111] Connection refused'))
2025-02-26 13:23:31,614 data_to_fw.py ERROR: Error : HTTPConnectionPool(host='127.0.0.1', port=7077): Max retries exceeded with url: /fwvision/qcinspection/update_qc_order (Caused by NewConnectionError('<urllib3.connection.HTTPConnection object at 0xffffac5acbe0>: Failed to establish a new connection: [Errno 111] Connection refused'))
2025-02-26 13:23:35,308 data_to_fw.py ERROR: Error : HTTPConnectionPool(host='127.0.0.1', port=7077): Max retries exceeded with url: /fwvision/qcinspection/update_qc_order (Caused by NewConnectionError('<urllib3.connection.HTTPConnection object at 0xffffac5ac3a0>: Failed to establish a new connection: [Errno 111] Connection refused'))
2025-02-26 13:23:39,304 data_to_fw.py ERROR: Error : HTTPConnectionPool(host='127.0.0.1', port=7077): Max retries exceeded with url: /fwvision/qcinspection/update_qc_order (Caused by NewConnectionError('<urllib3.connection.HTTPConnection object at 0xffffac5c48e0>: Failed to establish a new connection: [Errno 111] Connection refused'))
2025-02-26 13:23:43,013 data_to_fw.py ERROR: Error : HTTPConnectionPool(host='127.0.0.1', port=7077): Max retries exceeded with url: /fwvision/qcinspection/update_qc_order (Caused by NewConnectionError('<urllib3.connection.HTTPConnection object at 0xffffac63bbb0>: Failed to establish a new connection: [Errno 111] Connection refused'))
2025-02-26 13:23:46,723 data_to_fw.py ERROR: Error : HTTPConnectionPool(host='127.0.0.1', port=7077): Max retries exceeded with url: /fwvision/qcinspection/update_qc_order (Caused by NewConnectionError('<urllib3.connection.HTTPConnection object at 0xffffac63b550>: Failed to establish a new connection: [Errno 111] Connection refused'))
2025-02-26 13:23:50,439 data_to_fw.py ERROR: Error : HTTPConnectionPool(host='127.0.0.1', port=7077): Max retries exceeded with url: /fwvision/qcinspection/update_qc_order (Caused by NewConnectionError('<urllib3.connection.HTTPConnection object at 0xffffac5b9550>: Failed to establish a new connection: [Errno 111] Connection refused'))
2025-02-26 13:23:54,451 data_to_fw.py ERROR: Error : HTTPConnectionPool(host='127.0.0.1', port=7077): Max retries exceeded with url: /fwvision/qcinspection/update_qc_order (Caused by NewConnectionError('<urllib3.connection.HTTPConnection object at 0xffffac5c49d0>: Failed to establish a new connection: [Errno 111] Connection refused'))
2025-02-26 13:23:58,163 data_to_fw.py ERROR: Error : HTTPConnectionPool(host='127.0.0.1', port=7077): Max retries exceeded with url: /fwvision/qcinspection/update_qc_order (Caused by NewConnectionError('<urllib3.connection.HTTPConnection object at 0xffffac5ac490>: Failed to establish a new connection: [Errno 111] Connection refused'))
2025-02-26 13:24:01,850 data_to_fw.py ERROR: Error : HTTPConnectionPool(host='127.0.0.1', port=7077): Max retries exceeded with url: /fwvision/qcinspection/update_qc_order (Caused by NewConnectionError('<urllib3.connection.HTTPConnection object at 0xffffac5ac2e0>: Failed to establish a new connection: [Errno 111] Connection refused'))
2025-02-26 13:24:05,535 data_to_fw.py ERROR: Error : HTTPConnectionPool(host='127.0.0.1', port=7077): Max retries exceeded with url: /fwvision/qcinspection/update_qc_order (Caused by NewConnectionError('<urllib3.connection.HTTPConnection object at 0xffffac5b94f0>: Failed to establish a new connection: [Errno 111] Connection refused'))
2025-02-26 13:24:09,525 data_to_fw.py ERROR: Error : HTTPConnectionPool(host='127.0.0.1', port=7077): Max retries exceeded with url: /fwvision/qcinspection/update_qc_order (Caused by NewConnectionError('<urllib3.connection.HTTPConnection object at 0xffffac63bac0>: Failed to establish a new connection: [Errno 111] Connection refused'))
2025-02-26 13:24:13,220 data_to_fw.py ERROR: Error : HTTPConnectionPool(host='127.0.0.1', port=7077): Max retries exceeded with url: /fwvision/qcinspection/update_qc_order (Caused by NewConnectionError('<urllib3.connection.HTTPConnection object at 0xffffac5b9e20>: Failed to establish a new connection: [Errno 111] Connection refused'))
2025-02-26 13:24:16,914 data_to_fw.py ERROR: Error : HTTPConnectionPool(host='127.0.0.1', port=7077): Max retries exceeded with url: /fwvision/qcinspection/update_qc_order (Caused by NewConnectionError('<urllib3.connection.HTTPConnection object at 0xffffac5acc70>: Failed to establish a new connection: [Errno 111] Connection refused'))
2025-02-26 13:24:20,612 data_to_fw.py ERROR: Error : HTTPConnectionPool(host='127.0.0.1', port=7077): Max retries exceeded with url: /fwvision/qcinspection/update_qc_order (Caused by NewConnectionError('<urllib3.connection.HTTPConnection object at 0xffffac5acbb0>: Failed to establish a new connection: [Errno 111] Connection refused'))
2025-02-26 13:24:24,609 data_to_fw.py ERROR: Error : HTTPConnectionPool(host='127.0.0.1', port=7077): Max retries exceeded with url: /fwvision/qcinspection/update_qc_order (Caused by NewConnectionError('<urllib3.connection.HTTPConnection object at 0xffffac5c4250>: Failed to establish a new connection: [Errno 111] Connection refused'))
2025-02-26 13:24:28,309 data_to_fw.py ERROR: Error : HTTPConnectionPool(host='127.0.0.1', port=7077): Max retries exceeded with url: /fwvision/qcinspection/update_qc_order (Caused by NewConnectionError('<urllib3.connection.HTTPConnection object at 0xffffac617070>: Failed to establish a new connection: [Errno 111] Connection refused'))
2025-02-26 13:24:42,099 data_to_fw.py ERROR: Error : HTTPConnectionPool(host='127.0.0.1', port=7077): Max retries exceeded with url: /fwvision/qcinspection/update_qc_order (Caused by NewConnectionError('<urllib3.connection.HTTPConnection object at 0xffffac63b640>: Failed to establish a new connection: [Errno 111] Connection refused'))
2025-02-26 13:24:45,788 data_to_fw.py ERROR: Error : HTTPConnectionPool(host='127.0.0.1', port=7077): Max retries exceeded with url: /fwvision/qcinspection/update_qc_order (Caused by NewConnectionError('<urllib3.connection.HTTPConnection object at 0xffffac5ac3a0>: Failed to establish a new connection: [Errno 111] Connection refused'))
2025-02-26 13:24:49,808 data_to_fw.py ERROR: Error : HTTPConnectionPool(host='127.0.0.1', port=7077): Max retries exceeded with url: /fwvision/qcinspection/update_qc_order (Caused by NewConnectionError('<urllib3.connection.HTTPConnection object at 0xffffac5c4e50>: Failed to establish a new connection: [Errno 111] Connection refused'))
2025-02-26 13:24:53,512 data_to_fw.py ERROR: Error : HTTPConnectionPool(host='127.0.0.1', port=7077): Max retries exceeded with url: /fwvision/qcinspection/update_qc_order (Caused by NewConnectionError('<urllib3.connection.HTTPConnection object at 0xffffac5c47c0>: Failed to establish a new connection: [Errno 111] Connection refused'))
2025-02-26 13:24:57,220 data_to_fw.py ERROR: Error : HTTPConnectionPool(host='127.0.0.1', port=7077): Max retries exceeded with url: /fwvision/qcinspection/update_qc_order (Caused by NewConnectionError('<urllib3.connection.HTTPConnection object at 0xffffac63b790>: Failed to establish a new connection: [Errno 111] Connection refused'))
2025-02-26 13:25:00,925 data_to_fw.py ERROR: Error : HTTPConnectionPool(host='127.0.0.1', port=7077): Max retries exceeded with url: /fwvision/qcinspection/update_qc_order (Caused by NewConnectionError('<urllib3.connection.HTTPConnection object at 0xffffac5b9f40>: Failed to establish a new connection: [Errno 111] Connection refused'))
2025-02-26 13:25:04,950 data_to_fw.py ERROR: Error : HTTPConnectionPool(host='127.0.0.1', port=7077): Max retries exceeded with url: /fwvision/qcinspection/update_qc_order (Caused by NewConnectionError('<urllib3.connection.HTTPConnection object at 0xffffac63b250>: Failed to establish a new connection: [Errno 111] Connection refused'))
2025-02-26 13:25:08,669 data_to_fw.py ERROR: Error : HTTPConnectionPool(host='127.0.0.1', port=7077): Max retries exceeded with url: /fwvision/qcinspection/update_qc_order (Caused by NewConnectionError('<urllib3.connection.HTTPConnection object at 0xffffac63b670>: Failed to establish a new connection: [Errno 111] Connection refused'))
2025-02-26 13:25:12,383 data_to_fw.py ERROR: Error : HTTPConnectionPool(host='127.0.0.1', port=7077): Max retries exceeded with url: /fwvision/qcinspection/update_qc_order (Caused by NewConnectionError('<urllib3.connection.HTTPConnection object at 0xffffac5c43a0>: Failed to establish a new connection: [Errno 111] Connection refused'))
2025-02-26 13:25:16,072 data_to_fw.py ERROR: Error : HTTPConnectionPool(host='127.0.0.1', port=7077): Max retries exceeded with url: /fwvision/qcinspection/update_qc_order (Caused by NewConnectionError('<urllib3.connection.HTTPConnection object at 0xffffac5ac2b0>: Failed to establish a new connection: [Errno 111] Connection refused'))
2025-02-26 13:25:20,074 data_to_fw.py ERROR: Error : HTTPConnectionPool(host='127.0.0.1', port=7077): Max retries exceeded with url: /fwvision/qcinspection/update_qc_order (Caused by NewConnectionError('<urllib3.connection.HTTPConnection object at 0xffffac5ac5e0>: Failed to establish a new connection: [Errno 111] Connection refused'))
2025-02-26 13:25:23,810 data_to_fw.py ERROR: Error : HTTPConnectionPool(host='127.0.0.1', port=7077): Max retries exceeded with url: /fwvision/qcinspection/update_qc_order (Caused by NewConnectionError('<urllib3.connection.HTTPConnection object at 0xffffac5b9190>: Failed to establish a new connection: [Errno 111] Connection refused'))
2025-02-26 13:25:27,510 data_to_fw.py ERROR: Error : HTTPConnectionPool(host='127.0.0.1', port=7077): Max retries exceeded with url: /fwvision/qcinspection/update_qc_order (Caused by NewConnectionError('<urllib3.connection.HTTPConnection object at 0xffffac5c4910>: Failed to establish a new connection: [Errno 111] Connection refused'))
2025-02-26 13:25:31,215 data_to_fw.py ERROR: Error : HTTPConnectionPool(host='127.0.0.1', port=7077): Max retries exceeded with url: /fwvision/qcinspection/update_qc_order (Caused by NewConnectionError('<urllib3.connection.HTTPConnection object at 0xffffac5ac4f0>: Failed to establish a new connection: [Errno 111] Connection refused'))
2025-02-26 13:25:35,202 data_to_fw.py ERROR: Error : HTTPConnectionPool(host='127.0.0.1', port=7077): Max retries exceeded with url: /fwvision/qcinspection/update_qc_order (Caused by NewConnectionError('<urllib3.connection.HTTPConnection object at 0xffffac5ac040>: Failed to establish a new connection: [Errno 111] Connection refused'))
2025-02-26 13:25:38,904 data_to_fw.py ERROR: Error : HTTPConnectionPool(host='127.0.0.1', port=7077): Max retries exceeded with url: /fwvision/qcinspection/update_qc_order (Caused by NewConnectionError('<urllib3.connection.HTTPConnection object at 0xffffac5b9610>: Failed to establish a new connection: [Errno 111] Connection refused'))
2025-02-26 13:25:42,615 data_to_fw.py ERROR: Error : HTTPConnectionPool(host='127.0.0.1', port=7077): Max retries exceeded with url: /fwvision/qcinspection/update_qc_order (Caused by NewConnectionError('<urllib3.connection.HTTPConnection object at 0xffffac63ba30>: Failed to establish a new connection: [Errno 111] Connection refused'))
2025-02-26 13:25:46,311 data_to_fw.py ERROR: Error : HTTPConnectionPool(host='127.0.0.1', port=7077): Max retries exceeded with url: /fwvision/qcinspection/update_qc_order (Caused by NewConnectionError('<urllib3.connection.HTTPConnection object at 0xffffac5b9580>: Failed to establish a new connection: [Errno 111] Connection refused'))
2025-02-26 13:25:50,309 data_to_fw.py ERROR: Error : HTTPConnectionPool(host='127.0.0.1', port=7077): Max retries exceeded with url: /fwvision/qcinspection/update_qc_order (Caused by NewConnectionError('<urllib3.connection.HTTPConnection object at 0xffffac5ac1c0>: Failed to establish a new connection: [Errno 111] Connection refused'))
2025-02-26 13:25:54,001 data_to_fw.py ERROR: Error : HTTPConnectionPool(host='127.0.0.1', port=7077): Max retries exceeded with url: /fwvision/qcinspection/update_qc_order (Caused by NewConnectionError('<urllib3.connection.HTTPConnection object at 0xffffac5ac3a0>: Failed to establish a new connection: [Errno 111] Connection refused'))
2025-02-26 13:25:57,689 data_to_fw.py ERROR: Error : HTTPConnectionPool(host='127.0.0.1', port=7077): Max retries exceeded with url: /fwvision/qcinspection/update_qc_order (Caused by NewConnectionError('<urllib3.connection.HTTPConnection object at 0xffffac5c4fa0>: Failed to establish a new connection: [Errno 111] Connection refused'))
2025-02-26 13:26:01,382 data_to_fw.py ERROR: Error : HTTPConnectionPool(host='127.0.0.1', port=7077): Max retries exceeded with url: /fwvision/qcinspection/update_qc_order (Caused by NewConnectionError('<urllib3.connection.HTTPConnection object at 0xffffac617d30>: Failed to establish a new connection: [Errno 111] Connection refused'))
2025-02-26 13:26:05,373 data_to_fw.py ERROR: Error : HTTPConnectionPool(host='127.0.0.1', port=7077): Max retries exceeded with url: /fwvision/qcinspection/update_qc_order (Caused by NewConnectionError('<urllib3.connection.HTTPConnection object at 0xffffac63b1f0>: Failed to establish a new connection: [Errno 111] Connection refused'))
2025-02-26 13:26:09,064 data_to_fw.py ERROR: Error : HTTPConnectionPool(host='127.0.0.1', port=7077): Max retries exceeded with url: /fwvision/qcinspection/update_qc_order (Caused by NewConnectionError('<urllib3.connection.HTTPConnection object at 0xffffac5accd0>: Failed to establish a new connection: [Errno 111] Connection refused'))
2025-02-26 13:26:12,772 data_to_fw.py ERROR: Error : HTTPConnectionPool(host='127.0.0.1', port=7077): Max retries exceeded with url: /fwvision/qcinspection/update_qc_order (Caused by NewConnectionError('<urllib3.connection.HTTPConnection object at 0xffffac5c4280>: Failed to establish a new connection: [Errno 111] Connection refused'))
2025-02-26 13:26:16,470 data_to_fw.py ERROR: Error : HTTPConnectionPool(host='127.0.0.1', port=7077): Max retries exceeded with url: /fwvision/qcinspection/update_qc_order (Caused by NewConnectionError('<urllib3.connection.HTTPConnection object at 0xffffac5c4be0>: Failed to establish a new connection: [Errno 111] Connection refused'))
2025-02-26 13:26:20,465 data_to_fw.py ERROR: Error : HTTPConnectionPool(host='127.0.0.1', port=7077): Max retries exceeded with url: /fwvision/qcinspection/update_qc_order (Caused by NewConnectionError('<urllib3.connection.HTTPConnection object at 0xffffac63b5b0>: Failed to establish a new connection: [Errno 111] Connection refused'))
2025-02-26 13:26:24,163 data_to_fw.py ERROR: Error : HTTPConnectionPool(host='127.0.0.1', port=7077): Max retries exceeded with url: /fwvision/qcinspection/update_qc_order (Caused by NewConnectionError('<urllib3.connection.HTTPConnection object at 0xffffac5b94c0>: Failed to establish a new connection: [Errno 111] Connection refused'))
2025-02-26 13:26:27,855 data_to_fw.py ERROR: Error : HTTPConnectionPool(host='127.0.0.1', port=7077): Max retries exceeded with url: /fwvision/qcinspection/update_qc_order (Caused by NewConnectionError('<urllib3.connection.HTTPConnection object at 0xffffac63b700>: Failed to establish a new connection: [Errno 111] Connection refused'))
2025-02-26 13:26:31,541 data_to_fw.py ERROR: Error : HTTPConnectionPool(host='127.0.0.1', port=7077): Max retries exceeded with url: /fwvision/qcinspection/update_qc_order (Caused by NewConnectionError('<urllib3.connection.HTTPConnection object at 0xffffac63b490>: Failed to establish a new connection: [Errno 111] Connection refused'))
2025-02-26 13:26:35,538 data_to_fw.py ERROR: Error : HTTPConnectionPool(host='127.0.0.1', port=7077): Max retries exceeded with url: /fwvision/qcinspection/update_qc_order (Caused by NewConnectionError('<urllib3.connection.HTTPConnection object at 0xffffac5c4fd0>: Failed to establish a new connection: [Errno 111] Connection refused'))
2025-02-26 13:26:39,243 data_to_fw.py ERROR: Error : HTTPConnectionPool(host='127.0.0.1', port=7077): Max retries exceeded with url: /fwvision/qcinspection/update_qc_order (Caused by NewConnectionError('<urllib3.connection.HTTPConnection object at 0xffffac5ac550>: Failed to establish a new connection: [Errno 111] Connection refused'))
2025-02-26 13:26:42,937 data_to_fw.py ERROR: Error : HTTPConnectionPool(host='127.0.0.1', port=7077): Max retries exceeded with url: /fwvision/qcinspection/update_qc_order (Caused by NewConnectionError('<urllib3.connection.HTTPConnection object at 0xffffac5acb80>: Failed to establish a new connection: [Errno 111] Connection refused'))
2025-02-26 13:26:46,640 data_to_fw.py ERROR: Error : HTTPConnectionPool(host='127.0.0.1', port=7077): Max retries exceeded with url: /fwvision/qcinspection/update_qc_order (Caused by NewConnectionError('<urllib3.connection.HTTPConnection object at 0xffffac5b9100>: Failed to establish a new connection: [Errno 111] Connection refused'))
2025-02-26 13:26:50,648 data_to_fw.py ERROR: Error : HTTPConnectionPool(host='127.0.0.1', port=7077): Max retries exceeded with url: /fwvision/qcinspection/update_qc_order (Caused by NewConnectionError('<urllib3.connection.HTTPConnection object at 0xffffac5c4fa0>: Failed to establish a new connection: [Errno 111] Connection refused'))
2025-02-26 13:26:54,356 data_to_fw.py ERROR: Error : HTTPConnectionPool(host='127.0.0.1', port=7077): Max retries exceeded with url: /fwvision/qcinspection/update_qc_order (Caused by NewConnectionError('<urllib3.connection.HTTPConnection object at 0xffffac5acd60>: Failed to establish a new connection: [Errno 111] Connection refused'))
2025-02-26 13:26:58,063 data_to_fw.py ERROR: Error : HTTPConnectionPool(host='127.0.0.1', port=7077): Max retries exceeded with url: /fwvision/qcinspection/update_qc_order (Caused by NewConnectionError('<urllib3.connection.HTTPConnection object at 0xffffac5ac910>: Failed to establish a new connection: [Errno 111] Connection refused'))
2025-02-26 13:27:01,759 data_to_fw.py ERROR: Error : HTTPConnectionPool(host='127.0.0.1', port=7077): Max retries exceeded with url: /fwvision/qcinspection/update_qc_order (Caused by NewConnectionError('<urllib3.connection.HTTPConnection object at 0xffffac5b9f10>: Failed to establish a new connection: [Errno 111] Connection refused'))
2025-02-26 13:27:05,758 data_to_fw.py ERROR: Error : HTTPConnectionPool(host='127.0.0.1', port=7077): Max retries exceeded with url: /fwvision/qcinspection/update_qc_order (Caused by NewConnectionError('<urllib3.connection.HTTPConnection object at 0xffffac63bfd0>: Failed to establish a new connection: [Errno 111] Connection refused'))
2025-02-26 13:27:09,476 data_to_fw.py ERROR: Error : HTTPConnectionPool(host='127.0.0.1', port=7077): Max retries exceeded with url: /fwvision/qcinspection/update_qc_order (Caused by NewConnectionError('<urllib3.connection.HTTPConnection object at 0xffffac5b9820>: Failed to establish a new connection: [Errno 111] Connection refused'))
2025-02-26 13:27:13,190 data_to_fw.py ERROR: Error : HTTPConnectionPool(host='127.0.0.1', port=7077): Max retries exceeded with url: /fwvision/qcinspection/update_qc_order (Caused by NewConnectionError('<urllib3.connection.HTTPConnection object at 0xffffac5ac9a0>: Failed to establish a new connection: [Errno 111] Connection refused'))
2025-02-26 13:27:16,876 data_to_fw.py ERROR: Error : HTTPConnectionPool(host='127.0.0.1', port=7077): Max retries exceeded with url: /fwvision/qcinspection/update_qc_order (Caused by NewConnectionError('<urllib3.connection.HTTPConnection object at 0xffffac5accd0>: Failed to establish a new connection: [Errno 111] Connection refused'))
2025-02-26 13:27:20,875 data_to_fw.py ERROR: Error : HTTPConnectionPool(host='127.0.0.1', port=7077): Max retries exceeded with url: /fwvision/qcinspection/update_qc_order (Caused by NewConnectionError('<urllib3.connection.HTTPConnection object at 0xffffac5c4ee0>: Failed to establish a new connection: [Errno 111] Connection refused'))
2025-02-26 13:27:24,586 data_to_fw.py ERROR: Error : HTTPConnectionPool(host='127.0.0.1', port=7077): Max retries exceeded with url: /fwvision/qcinspection/update_qc_order (Caused by NewConnectionError('<urllib3.connection.HTTPConnection object at 0xffffac617130>: Failed to establish a new connection: [Errno 111] Connection refused'))
2025-02-26 13:27:28,276 data_to_fw.py ERROR: Error : HTTPConnectionPool(host='127.0.0.1', port=7077): Max retries exceeded with url: /fwvision/qcinspection/update_qc_order (Caused by NewConnectionError('<urllib3.connection.HTTPConnection object at 0xffffac63bd30>: Failed to establish a new connection: [Errno 111] Connection refused'))
2025-02-26 13:27:31,977 data_to_fw.py ERROR: Error : HTTPConnectionPool(host='127.0.0.1', port=7077): Max retries exceeded with url: /fwvision/qcinspection/update_qc_order (Caused by NewConnectionError('<urllib3.connection.HTTPConnection object at 0xffffac5acf10>: Failed to establish a new connection: [Errno 111] Connection refused'))
2025-02-26 13:27:35,976 data_to_fw.py ERROR: Error : HTTPConnectionPool(host='127.0.0.1', port=7077): Max retries exceeded with url: /fwvision/qcinspection/update_qc_order (Caused by NewConnectionError('<urllib3.connection.HTTPConnection object at 0xffffac5c4040>: Failed to establish a new connection: [Errno 111] Connection refused'))
2025-02-26 13:27:39,668 data_to_fw.py ERROR: Error : HTTPConnectionPool(host='127.0.0.1', port=7077): Max retries exceeded with url: /fwvision/qcinspection/update_qc_order (Caused by NewConnectionError('<urllib3.connection.HTTPConnection object at 0xffffac5c4190>: Failed to establish a new connection: [Errno 111] Connection refused'))
2025-02-26 13:27:43,364 data_to_fw.py ERROR: Error : HTTPConnectionPool(host='127.0.0.1', port=7077): Max retries exceeded with url: /fwvision/qcinspection/update_qc_order (Caused by NewConnectionError('<urllib3.connection.HTTPConnection object at 0xffffac63b6d0>: Failed to establish a new connection: [Errno 111] Connection refused'))
2025-02-26 13:27:47,053 data_to_fw.py ERROR: Error : HTTPConnectionPool(host='127.0.0.1', port=7077): Max retries exceeded with url: /fwvision/qcinspection/update_qc_order (Caused by NewConnectionError('<urllib3.connection.HTTPConnection object at 0xffffac5b9d90>: Failed to establish a new connection: [Errno 111] Connection refused'))
2025-02-26 13:27:51,053 data_to_fw.py ERROR: Error : HTTPConnectionPool(host='127.0.0.1', port=7077): Max retries exceeded with url: /fwvision/qcinspection/update_qc_order (Caused by NewConnectionError('<urllib3.connection.HTTPConnection object at 0xffffac63b730>: Failed to establish a new connection: [Errno 111] Connection refused'))
2025-02-26 13:27:54,749 data_to_fw.py ERROR: Error : HTTPConnectionPool(host='127.0.0.1', port=7077): Max retries exceeded with url: /fwvision/qcinspection/update_qc_order (Caused by NewConnectionError('<urllib3.connection.HTTPConnection object at 0xffffac63bbe0>: Failed to establish a new connection: [Errno 111] Connection refused'))
2025-02-26 13:27:58,444 data_to_fw.py ERROR: Error : HTTPConnectionPool(host='127.0.0.1', port=7077): Max retries exceeded with url: /fwvision/qcinspection/update_qc_order (Caused by NewConnectionError('<urllib3.connection.HTTPConnection object at 0xffffac5c4ac0>: Failed to establish a new connection: [Errno 111] Connection refused'))
2025-02-26 13:28:02,133 data_to_fw.py ERROR: Error : HTTPConnectionPool(host='127.0.0.1', port=7077): Max retries exceeded with url: /fwvision/qcinspection/update_qc_order (Caused by NewConnectionError('<urllib3.connection.HTTPConnection object at 0xffffac5acf70>: Failed to establish a new connection: [Errno 111] Connection refused'))
2025-02-26 13:28:06,128 data_to_fw.py ERROR: Error : HTTPConnectionPool(host='127.0.0.1', port=7077): Max retries exceeded with url: /fwvision/qcinspection/update_qc_order (Caused by NewConnectionError('<urllib3.connection.HTTPConnection object at 0xffffac5ac820>: Failed to establish a new connection: [Errno 111] Connection refused'))
2025-02-26 13:28:09,822 data_to_fw.py ERROR: Error : HTTPConnectionPool(host='127.0.0.1', port=7077): Max retries exceeded with url: /fwvision/qcinspection/update_qc_order (Caused by NewConnectionError('<urllib3.connection.HTTPConnection object at 0xffffac5b9550>: Failed to establish a new connection: [Errno 111] Connection refused'))
2025-02-26 13:28:13,515 data_to_fw.py ERROR: Error : HTTPConnectionPool(host='127.0.0.1', port=7077): Max retries exceeded with url: /fwvision/qcinspection/update_qc_order (Caused by NewConnectionError('<urllib3.connection.HTTPConnection object at 0xffffac5c4ee0>: Failed to establish a new connection: [Errno 111] Connection refused'))
2025-02-26 13:28:17,223 data_to_fw.py ERROR: Error : HTTPConnectionPool(host='127.0.0.1', port=7077): Max retries exceeded with url: /fwvision/qcinspection/update_qc_order (Caused by NewConnectionError('<urllib3.connection.HTTPConnection object at 0xffffac63bb20>: Failed to establish a new connection: [Errno 111] Connection refused'))
2025-02-26 13:28:21,219 data_to_fw.py ERROR: Error : HTTPConnectionPool(host='127.0.0.1', port=7077): Max retries exceeded with url: /fwvision/qcinspection/update_qc_order (Caused by NewConnectionError('<urllib3.connection.HTTPConnection object at 0xffffac63ba60>: Failed to establish a new connection: [Errno 111] Connection refused'))
2025-02-26 13:28:24,920 data_to_fw.py ERROR: Error : HTTPConnectionPool(host='127.0.0.1', port=7077): Max retries exceeded with url: /fwvision/qcinspection/update_qc_order (Caused by NewConnectionError('<urllib3.connection.HTTPConnection object at 0xffffac5b90a0>: Failed to establish a new connection: [Errno 111] Connection refused'))
2025-02-26 13:28:28,614 data_to_fw.py ERROR: Error : HTTPConnectionPool(host='127.0.0.1', port=7077): Max retries exceeded with url: /fwvision/qcinspection/update_qc_order (Caused by NewConnectionError('<urllib3.connection.HTTPConnection object at 0xffffac5acb20>: Failed to establish a new connection: [Errno 111] Connection refused'))
2025-02-26 13:28:32,317 data_to_fw.py ERROR: Error : HTTPConnectionPool(host='127.0.0.1', port=7077): Max retries exceeded with url: /fwvision/qcinspection/update_qc_order (Caused by NewConnectionError('<urllib3.connection.HTTPConnection object at 0xffffac5b9cd0>: Failed to establish a new connection: [Errno 111] Connection refused'))
2025-02-26 13:28:36,316 data_to_fw.py ERROR: Error : HTTPConnectionPool(host='127.0.0.1', port=7077): Max retries exceeded with url: /fwvision/qcinspection/update_qc_order (Caused by NewConnectionError('<urllib3.connection.HTTPConnection object at 0xffffac63b730>: Failed to establish a new connection: [Errno 111] Connection refused'))
2025-02-26 13:28:40,019 data_to_fw.py ERROR: Error : HTTPConnectionPool(host='127.0.0.1', port=7077): Max retries exceeded with url: /fwvision/qcinspection/update_qc_order (Caused by NewConnectionError('<urllib3.connection.HTTPConnection object at 0xffffac63bd00>: Failed to establish a new connection: [Errno 111] Connection refused'))
2025-02-26 13:28:43,728 data_to_fw.py ERROR: Error : HTTPConnectionPool(host='127.0.0.1', port=7077): Max retries exceeded with url: /fwvision/qcinspection/update_qc_order (Caused by NewConnectionError('<urllib3.connection.HTTPConnection object at 0xffffac5c4160>: Failed to establish a new connection: [Errno 111] Connection refused'))
2025-02-26 13:28:47,433 data_to_fw.py ERROR: Error : HTTPConnectionPool(host='127.0.0.1', port=7077): Max retries exceeded with url: /fwvision/qcinspection/update_qc_order (Caused by NewConnectionError('<urllib3.connection.HTTPConnection object at 0xffffac617d90>: Failed to establish a new connection: [Errno 111] Connection refused'))
2025-02-26 13:28:51,427 data_to_fw.py ERROR: Error : HTTPConnectionPool(host='127.0.0.1', port=7077): Max retries exceeded with url: /fwvision/qcinspection/update_qc_order (Caused by NewConnectionError('<urllib3.connection.HTTPConnection object at 0xffffac5acc70>: Failed to establish a new connection: [Errno 111] Connection refused'))
2025-02-26 13:28:55,123 data_to_fw.py ERROR: Error : HTTPConnectionPool(host='127.0.0.1', port=7077): Max retries exceeded with url: /fwvision/qcinspection/update_qc_order (Caused by NewConnectionError('<urllib3.connection.HTTPConnection object at 0xffffac63b310>: Failed to establish a new connection: [Errno 111] Connection refused'))
2025-02-26 13:28:58,831 data_to_fw.py ERROR: Error : HTTPConnectionPool(host='127.0.0.1', port=7077): Max retries exceeded with url: /fwvision/qcinspection/update_qc_order (Caused by NewConnectionError('<urllib3.connection.HTTPConnection object at 0xffffac5c4d30>: Failed to establish a new connection: [Errno 111] Connection refused'))
2025-02-26 13:29:02,526 data_to_fw.py ERROR: Error : HTTPConnectionPool(host='127.0.0.1', port=7077): Max retries exceeded with url: /fwvision/qcinspection/update_qc_order (Caused by NewConnectionError('<urllib3.connection.HTTPConnection object at 0xffffac5c4e50>: Failed to establish a new connection: [Errno 111] Connection refused'))
2025-02-26 13:29:06,523 data_to_fw.py ERROR: Error : HTTPConnectionPool(host='127.0.0.1', port=7077): Max retries exceeded with url: /fwvision/qcinspection/update_qc_order (Caused by NewConnectionError('<urllib3.connection.HTTPConnection object at 0xffffac5ac550>: Failed to establish a new connection: [Errno 111] Connection refused'))
2025-02-26 13:29:10,215 data_to_fw.py ERROR: Error : HTTPConnectionPool(host='127.0.0.1', port=7077): Max retries exceeded with url: /fwvision/qcinspection/update_qc_order (Caused by NewConnectionError('<urllib3.connection.HTTPConnection object at 0xffffac5b9310>: Failed to establish a new connection: [Errno 111] Connection refused'))
2025-02-26 13:29:13,918 data_to_fw.py ERROR: Error : HTTPConnectionPool(host='127.0.0.1', port=7077): Max retries exceeded with url: /fwvision/qcinspection/update_qc_order (Caused by NewConnectionError('<urllib3.connection.HTTPConnection object at 0xffffac5ac130>: Failed to establish a new connection: [Errno 111] Connection refused'))
2025-02-26 13:29:17,612 data_to_fw.py ERROR: Error : HTTPConnectionPool(host='127.0.0.1', port=7077): Max retries exceeded with url: /fwvision/qcinspection/update_qc_order (Caused by NewConnectionError('<urllib3.connection.HTTPConnection object at 0xffffac5acd00>: Failed to establish a new connection: [Errno 111] Connection refused'))
2025-02-26 13:29:21,600 data_to_fw.py ERROR: Error : HTTPConnectionPool(host='127.0.0.1', port=7077): Max retries exceeded with url: /fwvision/qcinspection/update_qc_order (Caused by NewConnectionError('<urllib3.connection.HTTPConnection object at 0xffffac5c4070>: Failed to establish a new connection: [Errno 111] Connection refused'))
2025-02-26 13:29:25,289 data_to_fw.py ERROR: Error : HTTPConnectionPool(host='127.0.0.1', port=7077): Max retries exceeded with url: /fwvision/qcinspection/update_qc_order (Caused by NewConnectionError('<urllib3.connection.HTTPConnection object at 0xffffac63bf40>: Failed to establish a new connection: [Errno 111] Connection refused'))
2025-02-26 13:29:28,977 data_to_fw.py ERROR: Error : HTTPConnectionPool(host='127.0.0.1', port=7077): Max retries exceeded with url: /fwvision/qcinspection/update_qc_order (Caused by NewConnectionError('<urllib3.connection.HTTPConnection object at 0xffffac63bd30>: Failed to establish a new connection: [Errno 111] Connection refused'))
2025-02-26 13:29:32,670 data_to_fw.py ERROR: Error : HTTPConnectionPool(host='127.0.0.1', port=7077): Max retries exceeded with url: /fwvision/qcinspection/update_qc_order (Caused by NewConnectionError('<urllib3.connection.HTTPConnection object at 0xffffac5b9f10>: Failed to establish a new connection: [Errno 111] Connection refused'))
2025-02-26 13:29:36,662 data_to_fw.py ERROR: Error : HTTPConnectionPool(host='127.0.0.1', port=7077): Max retries exceeded with url: /fwvision/qcinspection/update_qc_order (Caused by NewConnectionError('<urllib3.connection.HTTPConnection object at 0xffffac5c41c0>: Failed to establish a new connection: [Errno 111] Connection refused'))
2025-02-26 13:29:40,350 data_to_fw.py ERROR: Error : HTTPConnectionPool(host='127.0.0.1', port=7077): Max retries exceeded with url: /fwvision/qcinspection/update_qc_order (Caused by NewConnectionError('<urllib3.connection.HTTPConnection object at 0xffffac63bb50>: Failed to establish a new connection: [Errno 111] Connection refused'))
2025-02-26 13:29:44,048 data_to_fw.py ERROR: Error : HTTPConnectionPool(host='127.0.0.1', port=7077): Max retries exceeded with url: /fwvision/qcinspection/update_qc_order (Caused by NewConnectionError('<urllib3.connection.HTTPConnection object at 0xffffac63ba90>: Failed to establish a new connection: [Errno 111] Connection refused'))
2025-02-26 13:29:47,757 data_to_fw.py ERROR: Error : HTTPConnectionPool(host='127.0.0.1', port=7077): Max retries exceeded with url: /fwvision/qcinspection/update_qc_order (Caused by NewConnectionError('<urllib3.connection.HTTPConnection object at 0xffffac5b9670>: Failed to establish a new connection: [Errno 111] Connection refused'))
2025-02-26 13:29:51,768 data_to_fw.py ERROR: Error : HTTPConnectionPool(host='127.0.0.1', port=7077): Max retries exceeded with url: /fwvision/qcinspection/update_qc_order (Caused by NewConnectionError('<urllib3.connection.HTTPConnection object at 0xffffac5ac070>: Failed to establish a new connection: [Errno 111] Connection refused'))
2025-02-26 13:29:55,475 data_to_fw.py ERROR: Error : HTTPConnectionPool(host='127.0.0.1', port=7077): Max retries exceeded with url: /fwvision/qcinspection/update_qc_order (Caused by NewConnectionError('<urllib3.connection.HTTPConnection object at 0xffffac5b9f70>: Failed to establish a new connection: [Errno 111] Connection refused'))
2025-02-26 13:29:59,169 data_to_fw.py ERROR: Error : HTTPConnectionPool(host='127.0.0.1', port=7077): Max retries exceeded with url: /fwvision/qcinspection/update_qc_order (Caused by NewConnectionError('<urllib3.connection.HTTPConnection object at 0xffffac63b820>: Failed to establish a new connection: [Errno 111] Connection refused'))
2025-02-26 13:30:02,865 data_to_fw.py ERROR: Error : HTTPConnectionPool(host='127.0.0.1', port=7077): Max retries exceeded with url: /fwvision/qcinspection/update_qc_order (Caused by NewConnectionError('<urllib3.connection.HTTPConnection object at 0xffffac63b2b0>: Failed to establish a new connection: [Errno 111] Connection refused'))
2025-02-26 13:30:06,883 data_to_fw.py ERROR: Error : HTTPConnectionPool(host='127.0.0.1', port=7077): Max retries exceeded with url: /fwvision/qcinspection/update_qc_order (Caused by NewConnectionError('<urllib3.connection.HTTPConnection object at 0xffffac5c4940>: Failed to establish a new connection: [Errno 111] Connection refused'))
2025-02-26 13:30:10,582 data_to_fw.py ERROR: Error : HTTPConnectionPool(host='127.0.0.1', port=7077): Max retries exceeded with url: /fwvision/qcinspection/update_qc_order (Caused by NewConnectionError('<urllib3.connection.HTTPConnection object at 0xffffac617dc0>: Failed to establish a new connection: [Errno 111] Connection refused'))
2025-02-26 13:30:14,287 data_to_fw.py ERROR: Error : HTTPConnectionPool(host='127.0.0.1', port=7077): Max retries exceeded with url: /fwvision/qcinspection/update_qc_order (Caused by NewConnectionError('<urllib3.connection.HTTPConnection object at 0xffffac5ac250>: Failed to establish a new connection: [Errno 111] Connection refused'))
2025-02-26 13:30:17,974 data_to_fw.py ERROR: Error : HTTPConnectionPool(host='127.0.0.1', port=7077): Max retries exceeded with url: /fwvision/qcinspection/update_qc_order (Caused by NewConnectionError('<urllib3.connection.HTTPConnection object at 0xffffac63bc40>: Failed to establish a new connection: [Errno 111] Connection refused'))
2025-02-26 13:30:21,969 data_to_fw.py ERROR: Error : HTTPConnectionPool(host='127.0.0.1', port=7077): Max retries exceeded with url: /fwvision/qcinspection/update_qc_order (Caused by NewConnectionError('<urllib3.connection.HTTPConnection object at 0xffffac5c4d30>: Failed to establish a new connection: [Errno 111] Connection refused'))
2025-02-26 13:30:25,673 data_to_fw.py ERROR: Error : HTTPConnectionPool(host='127.0.0.1', port=7077): Max retries exceeded with url: /fwvision/qcinspection/update_qc_order (Caused by NewConnectionError('<urllib3.connection.HTTPConnection object at 0xffffac5c4f10>: Failed to establish a new connection: [Errno 111] Connection refused'))
2025-02-26 13:30:29,378 data_to_fw.py ERROR: Error : HTTPConnectionPool(host='127.0.0.1', port=7077): Max retries exceeded with url: /fwvision/qcinspection/update_qc_order (Caused by NewConnectionError('<urllib3.connection.HTTPConnection object at 0xffffac5acd60>: Failed to establish a new connection: [Errno 111] Connection refused'))
2025-02-26 13:30:33,070 data_to_fw.py ERROR: Error : HTTPConnectionPool(host='127.0.0.1', port=7077): Max retries exceeded with url: /fwvision/qcinspection/update_qc_order (Caused by NewConnectionError('<urllib3.connection.HTTPConnection object at 0xffffac5b9610>: Failed to establish a new connection: [Errno 111] Connection refused'))
2025-02-26 13:30:37,064 data_to_fw.py ERROR: Error : HTTPConnectionPool(host='127.0.0.1', port=7077): Max retries exceeded with url: /fwvision/qcinspection/update_qc_order (Caused by NewConnectionError('<urllib3.connection.HTTPConnection object at 0xffffac5ac130>: Failed to establish a new connection: [Errno 111] Connection refused'))
2025-02-26 13:30:40,750 data_to_fw.py ERROR: Error : HTTPConnectionPool(host='127.0.0.1', port=7077): Max retries exceeded with url: /fwvision/qcinspection/update_qc_order (Caused by NewConnectionError('<urllib3.connection.HTTPConnection object at 0xffffac5acf10>: Failed to establish a new connection: [Errno 111] Connection refused'))
2025-02-26 13:30:44,445 data_to_fw.py ERROR: Error : HTTPConnectionPool(host='127.0.0.1', port=7077): Max retries exceeded with url: /fwvision/qcinspection/update_qc_order (Caused by NewConnectionError('<urllib3.connection.HTTPConnection object at 0xffffac5c41f0>: Failed to establish a new connection: [Errno 111] Connection refused'))
2025-02-26 13:30:48,139 data_to_fw.py ERROR: Error : HTTPConnectionPool(host='127.0.0.1', port=7077): Max retries exceeded with url: /fwvision/qcinspection/update_qc_order (Caused by NewConnectionError('<urllib3.connection.HTTPConnection object at 0xffffac63bbb0>: Failed to establish a new connection: [Errno 111] Connection refused'))
2025-02-26 13:30:52,137 data_to_fw.py ERROR: Error : HTTPConnectionPool(host='127.0.0.1', port=7077): Max retries exceeded with url: /fwvision/qcinspection/update_qc_order (Caused by NewConnectionError('<urllib3.connection.HTTPConnection object at 0xffffac63be50>: Failed to establish a new connection: [Errno 111] Connection refused'))
2025-02-26 13:30:55,831 data_to_fw.py ERROR: Error : HTTPConnectionPool(host='127.0.0.1', port=7077): Max retries exceeded with url: /fwvision/qcinspection/update_qc_order (Caused by NewConnectionError('<urllib3.connection.HTTPConnection object at 0xffffac5b9640>: Failed to establish a new connection: [Errno 111] Connection refused'))
2025-02-26 13:30:59,543 data_to_fw.py ERROR: Error : HTTPConnectionPool(host='127.0.0.1', port=7077): Max retries exceeded with url: /fwvision/qcinspection/update_qc_order (Caused by NewConnectionError('<urllib3.connection.HTTPConnection object at 0xffffac5c4c70>: Failed to establish a new connection: [Errno 111] Connection refused'))
2025-02-26 13:31:03,260 data_to_fw.py ERROR: Error : HTTPConnectionPool(host='127.0.0.1', port=7077): Max retries exceeded with url: /fwvision/qcinspection/update_qc_order (Caused by NewConnectionError('<urllib3.connection.HTTPConnection object at 0xffffac63b2b0>: Failed to establish a new connection: [Errno 111] Connection refused'))
2025-02-26 13:31:07,275 data_to_fw.py ERROR: Error : HTTPConnectionPool(host='127.0.0.1', port=7077): Max retries exceeded with url: /fwvision/qcinspection/update_qc_order (Caused by NewConnectionError('<urllib3.connection.HTTPConnection object at 0xffffac63b3d0>: Failed to establish a new connection: [Errno 111] Connection refused'))
2025-02-26 13:31:11,000 data_to_fw.py ERROR: Error : HTTPConnectionPool(host='127.0.0.1', port=7077): Max retries exceeded with url: /fwvision/qcinspection/update_qc_order (Caused by NewConnectionError('<urllib3.connection.HTTPConnection object at 0xffffac5b9d00>: Failed to establish a new connection: [Errno 111] Connection refused'))
2025-02-26 13:31:14,711 data_to_fw.py ERROR: Error : HTTPConnectionPool(host='127.0.0.1', port=7077): Max retries exceeded with url: /fwvision/qcinspection/update_qc_order (Caused by NewConnectionError('<urllib3.connection.HTTPConnection object at 0xffffac5ac4f0>: Failed to establish a new connection: [Errno 111] Connection refused'))
2025-02-26 13:31:18,422 data_to_fw.py ERROR: Error : HTTPConnectionPool(host='127.0.0.1', port=7077): Max retries exceeded with url: /fwvision/qcinspection/update_qc_order (Caused by NewConnectionError('<urllib3.connection.HTTPConnection object at 0xffffac5b9580>: Failed to establish a new connection: [Errno 111] Connection refused'))
2025-02-26 13:31:22,424 data_to_fw.py ERROR: Error : HTTPConnectionPool(host='127.0.0.1', port=7077): Max retries exceeded with url: /fwvision/qcinspection/update_qc_order (Caused by NewConnectionError('<urllib3.connection.HTTPConnection object at 0xffffac63b040>: Failed to establish a new connection: [Errno 111] Connection refused'))
2025-02-26 13:31:26,121 data_to_fw.py ERROR: Error : HTTPConnectionPool(host='127.0.0.1', port=7077): Max retries exceeded with url: /fwvision/qcinspection/update_qc_order (Caused by NewConnectionError('<urllib3.connection.HTTPConnection object at 0xffffac63b9d0>: Failed to establish a new connection: [Errno 111] Connection refused'))
2025-02-26 13:31:29,836 data_to_fw.py ERROR: Error : HTTPConnectionPool(host='127.0.0.1', port=7077): Max retries exceeded with url: /fwvision/qcinspection/update_qc_order (Caused by NewConnectionError('<urllib3.connection.HTTPConnection object at 0xffffac5c4bb0>: Failed to establish a new connection: [Errno 111] Connection refused'))
2025-02-26 13:31:33,541 data_to_fw.py ERROR: Error : HTTPConnectionPool(host='127.0.0.1', port=7077): Max retries exceeded with url: /fwvision/qcinspection/update_qc_order (Caused by NewConnectionError('<urllib3.connection.HTTPConnection object at 0xffffac6171c0>: Failed to establish a new connection: [Errno 111] Connection refused'))
2025-02-26 13:31:37,542 data_to_fw.py ERROR: Error : HTTPConnectionPool(host='127.0.0.1', port=7077): Max retries exceeded with url: /fwvision/qcinspection/update_qc_order (Caused by NewConnectionError('<urllib3.connection.HTTPConnection object at 0xffffac5aceb0>: Failed to establish a new connection: [Errno 111] Connection refused'))
2025-02-26 13:31:41,226 data_to_fw.py ERROR: Error : HTTPConnectionPool(host='127.0.0.1', port=7077): Max retries exceeded with url: /fwvision/qcinspection/update_qc_order (Caused by NewConnectionError('<urllib3.connection.HTTPConnection object at 0xffffac63be20>: Failed to establish a new connection: [Errno 111] Connection refused'))
2025-02-26 13:31:44,915 data_to_fw.py ERROR: Error : HTTPConnectionPool(host='127.0.0.1', port=7077): Max retries exceeded with url: /fwvision/qcinspection/update_qc_order (Caused by NewConnectionError('<urllib3.connection.HTTPConnection object at 0xffffac5c4130>: Failed to establish a new connection: [Errno 111] Connection refused'))
2025-02-26 13:31:48,608 data_to_fw.py ERROR: Error : HTTPConnectionPool(host='127.0.0.1', port=7077): Max retries exceeded with url: /fwvision/qcinspection/update_qc_order (Caused by NewConnectionError('<urllib3.connection.HTTPConnection object at 0xffffac5c46a0>: Failed to establish a new connection: [Errno 111] Connection refused'))
2025-02-26 13:31:52,620 data_to_fw.py ERROR: Error : HTTPConnectionPool(host='127.0.0.1', port=7077): Max retries exceeded with url: /fwvision/qcinspection/update_qc_order (Caused by NewConnectionError('<urllib3.connection.HTTPConnection object at 0xffffac5acf70>: Failed to establish a new connection: [Errno 111] Connection refused'))
2025-02-26 13:31:56,318 data_to_fw.py ERROR: Error : HTTPConnectionPool(host='127.0.0.1', port=7077): Max retries exceeded with url: /fwvision/qcinspection/update_qc_order (Caused by NewConnectionError('<urllib3.connection.HTTPConnection object at 0xffffac5b9670>: Failed to establish a new connection: [Errno 111] Connection refused'))
2025-02-26 13:32:00,022 data_to_fw.py ERROR: Error : HTTPConnectionPool(host='127.0.0.1', port=7077): Max retries exceeded with url: /fwvision/qcinspection/update_qc_order (Caused by NewConnectionError('<urllib3.connection.HTTPConnection object at 0xffffac5ac130>: Failed to establish a new connection: [Errno 111] Connection refused'))
2025-02-26 13:32:03,702 data_to_fw.py ERROR: Error : HTTPConnectionPool(host='127.0.0.1', port=7077): Max retries exceeded with url: /fwvision/qcinspection/update_qc_order (Caused by NewConnectionError('<urllib3.connection.HTTPConnection object at 0xffffac5ac460>: Failed to establish a new connection: [Errno 111] Connection refused'))
2025-02-26 13:32:07,697 data_to_fw.py ERROR: Error : HTTPConnectionPool(host='127.0.0.1', port=7077): Max retries exceeded with url: /fwvision/qcinspection/update_qc_order (Caused by NewConnectionError('<urllib3.connection.HTTPConnection object at 0xffffac5c4340>: Failed to establish a new connection: [Errno 111] Connection refused'))
2025-02-26 13:32:11,390 data_to_fw.py ERROR: Error : HTTPConnectionPool(host='127.0.0.1', port=7077): Max retries exceeded with url: /fwvision/qcinspection/update_qc_order (Caused by NewConnectionError('<urllib3.connection.HTTPConnection object at 0xffffac63b250>: Failed to establish a new connection: [Errno 111] Connection refused'))
2025-02-26 13:32:15,084 data_to_fw.py ERROR: Error : HTTPConnectionPool(host='127.0.0.1', port=7077): Max retries exceeded with url: /fwvision/qcinspection/update_qc_order (Caused by NewConnectionError('<urllib3.connection.HTTPConnection object at 0xffffac63beb0>: Failed to establish a new connection: [Errno 111] Connection refused'))
2025-02-26 13:32:18,786 data_to_fw.py ERROR: Error : HTTPConnectionPool(host='127.0.0.1', port=7077): Max retries exceeded with url: /fwvision/qcinspection/update_qc_order (Caused by NewConnectionError('<urllib3.connection.HTTPConnection object at 0xffffac5b9490>: Failed to establish a new connection: [Errno 111] Connection refused'))
2025-02-26 13:32:22,783 data_to_fw.py ERROR: Error : HTTPConnectionPool(host='127.0.0.1', port=7077): Max retries exceeded with url: /fwvision/qcinspection/update_qc_order (Caused by NewConnectionError('<urllib3.connection.HTTPConnection object at 0xffffac5c4280>: Failed to establish a new connection: [Errno 111] Connection refused'))
2025-02-26 13:32:26,469 data_to_fw.py ERROR: Error : HTTPConnectionPool(host='127.0.0.1', port=7077): Max retries exceeded with url: /fwvision/qcinspection/update_qc_order (Caused by NewConnectionError('<urllib3.connection.HTTPConnection object at 0xffffac5ac580>: Failed to establish a new connection: [Errno 111] Connection refused'))
2025-02-26 13:32:30,162 data_to_fw.py ERROR: Error : HTTPConnectionPool(host='127.0.0.1', port=7077): Max retries exceeded with url: /fwvision/qcinspection/update_qc_order (Caused by NewConnectionError('<urllib3.connection.HTTPConnection object at 0xffffac5ac3d0>: Failed to establish a new connection: [Errno 111] Connection refused'))
2025-02-26 13:32:33,874 data_to_fw.py ERROR: Error : HTTPConnectionPool(host='127.0.0.1', port=7077): Max retries exceeded with url: /fwvision/qcinspection/update_qc_order (Caused by NewConnectionError('<urllib3.connection.HTTPConnection object at 0xffffac5b94c0>: Failed to establish a new connection: [Errno 111] Connection refused'))
2025-02-26 13:32:37,872 data_to_fw.py ERROR: Error : HTTPConnectionPool(host='127.0.0.1', port=7077): Max retries exceeded with url: /fwvision/qcinspection/update_qc_order (Caused by NewConnectionError('<urllib3.connection.HTTPConnection object at 0xffffac63bc70>: Failed to establish a new connection: [Errno 111] Connection refused'))
2025-02-26 13:32:41,579 data_to_fw.py ERROR: Error : HTTPConnectionPool(host='127.0.0.1', port=7077): Max retries exceeded with url: /fwvision/qcinspection/update_qc_order (Caused by NewConnectionError('<urllib3.connection.HTTPConnection object at 0xffffac5b9ee0>: Failed to establish a new connection: [Errno 111] Connection refused'))
2025-02-26 13:32:45,265 data_to_fw.py ERROR: Error : HTTPConnectionPool(host='127.0.0.1', port=7077): Max retries exceeded with url: /fwvision/qcinspection/update_qc_order (Caused by NewConnectionError('<urllib3.connection.HTTPConnection object at 0xffffac5ac4c0>: Failed to establish a new connection: [Errno 111] Connection refused'))
2025-02-26 13:32:48,963 data_to_fw.py ERROR: Error : HTTPConnectionPool(host='127.0.0.1', port=7077): Max retries exceeded with url: /fwvision/qcinspection/update_qc_order (Caused by NewConnectionError('<urllib3.connection.HTTPConnection object at 0xffffac5acc70>: Failed to establish a new connection: [Errno 111] Connection refused'))
2025-02-26 13:32:52,962 data_to_fw.py ERROR: Error : HTTPConnectionPool(host='127.0.0.1', port=7077): Max retries exceeded with url: /fwvision/qcinspection/update_qc_order (Caused by NewConnectionError('<urllib3.connection.HTTPConnection object at 0xffffac5c44c0>: Failed to establish a new connection: [Errno 111] Connection refused'))
2025-02-26 13:32:56,666 data_to_fw.py ERROR: Error : HTTPConnectionPool(host='127.0.0.1', port=7077): Max retries exceeded with url: /fwvision/qcinspection/update_qc_order (Caused by NewConnectionError('<urllib3.connection.HTTPConnection object at 0xffffac617c40>: Failed to establish a new connection: [Errno 111] Connection refused'))
2025-02-26 13:33:00,372 data_to_fw.py ERROR: Error : HTTPConnectionPool(host='127.0.0.1', port=7077): Max retries exceeded with url: /fwvision/qcinspection/update_qc_order (Caused by NewConnectionError('<urllib3.connection.HTTPConnection object at 0xffffac63bfa0>: Failed to establish a new connection: [Errno 111] Connection refused'))
2025-02-26 13:33:04,082 data_to_fw.py ERROR: Error : HTTPConnectionPool(host='127.0.0.1', port=7077): Max retries exceeded with url: /fwvision/qcinspection/update_qc_order (Caused by NewConnectionError('<urllib3.connection.HTTPConnection object at 0xffffac5ac460>: Failed to establish a new connection: [Errno 111] Connection refused'))
2025-02-26 13:33:08,079 data_to_fw.py ERROR: Error : HTTPConnectionPool(host='127.0.0.1', port=7077): Max retries exceeded with url: /fwvision/qcinspection/update_qc_order (Caused by NewConnectionError('<urllib3.connection.HTTPConnection object at 0xffffac5c4400>: Failed to establish a new connection: [Errno 111] Connection refused'))
2025-02-26 13:33:11,778 data_to_fw.py ERROR: Error : HTTPConnectionPool(host='127.0.0.1', port=7077): Max retries exceeded with url: /fwvision/qcinspection/update_qc_order (Caused by NewConnectionError('<urllib3.connection.HTTPConnection object at 0xffffac5c4fd0>: Failed to establish a new connection: [Errno 111] Connection refused'))
2025-02-26 13:33:15,480 data_to_fw.py ERROR: Error : HTTPConnectionPool(host='127.0.0.1', port=7077): Max retries exceeded with url: /fwvision/qcinspection/update_qc_order (Caused by NewConnectionError('<urllib3.connection.HTTPConnection object at 0xffffac63b2b0>: Failed to establish a new connection: [Errno 111] Connection refused'))
2025-02-26 13:33:19,174 data_to_fw.py ERROR: Error : HTTPConnectionPool(host='127.0.0.1', port=7077): Max retries exceeded with url: /fwvision/qcinspection/update_qc_order (Caused by NewConnectionError('<urllib3.connection.HTTPConnection object at 0xffffac5b97f0>: Failed to establish a new connection: [Errno 111] Connection refused'))
2025-02-26 13:33:23,169 data_to_fw.py ERROR: Error : HTTPConnectionPool(host='127.0.0.1', port=7077): Max retries exceeded with url: /fwvision/qcinspection/update_qc_order (Caused by NewConnectionError('<urllib3.connection.HTTPConnection object at 0xffffac63b7c0>: Failed to establish a new connection: [Errno 111] Connection refused'))
2025-02-26 13:33:26,855 data_to_fw.py ERROR: Error : HTTPConnectionPool(host='127.0.0.1', port=7077): Max retries exceeded with url: /fwvision/qcinspection/update_qc_order (Caused by NewConnectionError('<urllib3.connection.HTTPConnection object at 0xffffac63bc40>: Failed to establish a new connection: [Errno 111] Connection refused'))
2025-02-26 13:33:30,560 data_to_fw.py ERROR: Error : HTTPConnectionPool(host='127.0.0.1', port=7077): Max retries exceeded with url: /fwvision/qcinspection/update_qc_order (Caused by NewConnectionError('<urllib3.connection.HTTPConnection object at 0xffffac5c4ac0>: Failed to establish a new connection: [Errno 111] Connection refused'))
2025-02-26 13:33:34,262 data_to_fw.py ERROR: Error : HTTPConnectionPool(host='127.0.0.1', port=7077): Max retries exceeded with url: /fwvision/qcinspection/update_qc_order (Caused by NewConnectionError('<urllib3.connection.HTTPConnection object at 0xffffac5ac6a0>: Failed to establish a new connection: [Errno 111] Connection refused'))
2025-02-26 13:33:38,266 data_to_fw.py ERROR: Error : HTTPConnectionPool(host='127.0.0.1', port=7077): Max retries exceeded with url: /fwvision/qcinspection/update_qc_order (Caused by NewConnectionError('<urllib3.connection.HTTPConnection object at 0xffffac5ac160>: Failed to establish a new connection: [Errno 111] Connection refused'))
2025-02-26 13:33:41,985 data_to_fw.py ERROR: Error : HTTPConnectionPool(host='127.0.0.1', port=7077): Max retries exceeded with url: /fwvision/qcinspection/update_qc_order (Caused by NewConnectionError('<urllib3.connection.HTTPConnection object at 0xffffac5b9370>: Failed to establish a new connection: [Errno 111] Connection refused'))
2025-02-26 13:33:45,690 data_to_fw.py ERROR: Error : HTTPConnectionPool(host='127.0.0.1', port=7077): Max retries exceeded with url: /fwvision/qcinspection/update_qc_order (Caused by NewConnectionError('<urllib3.connection.HTTPConnection object at 0xffffac5c44c0>: Failed to establish a new connection: [Errno 111] Connection refused'))
2025-02-26 13:33:49,376 data_to_fw.py ERROR: Error : HTTPConnectionPool(host='127.0.0.1', port=7077): Max retries exceeded with url: /fwvision/qcinspection/update_qc_order (Caused by NewConnectionError('<urllib3.connection.HTTPConnection object at 0xffffac5ac3a0>: Failed to establish a new connection: [Errno 111] Connection refused'))
2025-02-26 13:33:53,379 data_to_fw.py ERROR: Error : HTTPConnectionPool(host='127.0.0.1', port=7077): Max retries exceeded with url: /fwvision/qcinspection/update_qc_order (Caused by NewConnectionError('<urllib3.connection.HTTPConnection object at 0xffffac5acdf0>: Failed to establish a new connection: [Errno 111] Connection refused'))
2025-02-26 13:33:57,086 data_to_fw.py ERROR: Error : HTTPConnectionPool(host='127.0.0.1', port=7077): Max retries exceeded with url: /fwvision/qcinspection/update_qc_order (Caused by NewConnectionError('<urllib3.connection.HTTPConnection object at 0xffffac5b9640>: Failed to establish a new connection: [Errno 111] Connection refused'))
2025-02-26 13:34:00,795 data_to_fw.py ERROR: Error : HTTPConnectionPool(host='127.0.0.1', port=7077): Max retries exceeded with url: /fwvision/qcinspection/update_qc_order (Caused by NewConnectionError('<urllib3.connection.HTTPConnection object at 0xffffac63be20>: Failed to establish a new connection: [Errno 111] Connection refused'))
2025-02-26 13:34:04,490 data_to_fw.py ERROR: Error : HTTPConnectionPool(host='127.0.0.1', port=7077): Max retries exceeded with url: /fwvision/qcinspection/update_qc_order (Caused by NewConnectionError('<urllib3.connection.HTTPConnection object at 0xffffac5b9ca0>: Failed to establish a new connection: [Errno 111] Connection refused'))
2025-02-26 13:34:08,486 data_to_fw.py ERROR: Error : HTTPConnectionPool(host='127.0.0.1', port=7077): Max retries exceeded with url: /fwvision/qcinspection/update_qc_order (Caused by NewConnectionError('<urllib3.connection.HTTPConnection object at 0xffffac5ac2e0>: Failed to establish a new connection: [Errno 111] Connection refused'))
2025-02-26 13:34:12,194 data_to_fw.py ERROR: Error : HTTPConnectionPool(host='127.0.0.1', port=7077): Max retries exceeded with url: /fwvision/qcinspection/update_qc_order (Caused by NewConnectionError('<urllib3.connection.HTTPConnection object at 0xffffac5ac460>: Failed to establish a new connection: [Errno 111] Connection refused'))
2025-02-26 13:34:15,905 data_to_fw.py ERROR: Error : HTTPConnectionPool(host='127.0.0.1', port=7077): Max retries exceeded with url: /fwvision/qcinspection/update_qc_order (Caused by NewConnectionError('<urllib3.connection.HTTPConnection object at 0xffffac5c4250>: Failed to establish a new connection: [Errno 111] Connection refused'))
2025-02-26 13:34:19,603 data_to_fw.py ERROR: Error : HTTPConnectionPool(host='127.0.0.1', port=7077): Max retries exceeded with url: /fwvision/qcinspection/update_qc_order (Caused by NewConnectionError('<urllib3.connection.HTTPConnection object at 0xffffac617d30>: Failed to establish a new connection: [Errno 111] Connection refused'))
2025-02-26 13:34:23,602 data_to_fw.py ERROR: Error : HTTPConnectionPool(host='127.0.0.1', port=7077): Max retries exceeded with url: /fwvision/qcinspection/update_qc_order (Caused by NewConnectionError('<urllib3.connection.HTTPConnection object at 0xffffac63b9d0>: Failed to establish a new connection: [Errno 111] Connection refused'))
2025-02-26 13:34:27,315 data_to_fw.py ERROR: Error : HTTPConnectionPool(host='127.0.0.1', port=7077): Max retries exceeded with url: /fwvision/qcinspection/update_qc_order (Caused by NewConnectionError('<urllib3.connection.HTTPConnection object at 0xffffac5ac430>: Failed to establish a new connection: [Errno 111] Connection refused'))
2025-02-26 13:34:31,001 data_to_fw.py ERROR: Error : HTTPConnectionPool(host='127.0.0.1', port=7077): Max retries exceeded with url: /fwvision/qcinspection/update_qc_order (Caused by NewConnectionError('<urllib3.connection.HTTPConnection object at 0xffffac5c4850>: Failed to establish a new connection: [Errno 111] Connection refused'))
2025-02-26 13:34:34,697 data_to_fw.py ERROR: Error : HTTPConnectionPool(host='127.0.0.1', port=7077): Max retries exceeded with url: /fwvision/qcinspection/update_qc_order (Caused by NewConnectionError('<urllib3.connection.HTTPConnection object at 0xffffac5c4820>: Failed to establish a new connection: [Errno 111] Connection refused'))
2025-02-26 13:34:38,690 data_to_fw.py ERROR: Error : HTTPConnectionPool(host='127.0.0.1', port=7077): Max retries exceeded with url: /fwvision/qcinspection/update_qc_order (Caused by NewConnectionError('<urllib3.connection.HTTPConnection object at 0xffffac63b1c0>: Failed to establish a new connection: [Errno 111] Connection refused'))
2025-02-26 13:34:42,391 data_to_fw.py ERROR: Error : HTTPConnectionPool(host='127.0.0.1', port=7077): Max retries exceeded with url: /fwvision/qcinspection/update_qc_order (Caused by NewConnectionError('<urllib3.connection.HTTPConnection object at 0xffffac5b9d00>: Failed to establish a new connection: [Errno 111] Connection refused'))
2025-02-26 13:34:46,116 data_to_fw.py ERROR: Error : HTTPConnectionPool(host='127.0.0.1', port=7077): Max retries exceeded with url: /fwvision/qcinspection/update_qc_order (Caused by NewConnectionError('<urllib3.connection.HTTPConnection object at 0xffffac63b820>: Failed to establish a new connection: [Errno 111] Connection refused'))
2025-02-26 13:34:49,821 data_to_fw.py ERROR: Error : HTTPConnectionPool(host='127.0.0.1', port=7077): Max retries exceeded with url: /fwvision/qcinspection/update_qc_order (Caused by NewConnectionError('<urllib3.connection.HTTPConnection object at 0xffffac63b790>: Failed to establish a new connection: [Errno 111] Connection refused'))
2025-02-26 13:34:53,833 data_to_fw.py ERROR: Error : HTTPConnectionPool(host='127.0.0.1', port=7077): Max retries exceeded with url: /fwvision/qcinspection/update_qc_order (Caused by NewConnectionError('<urllib3.connection.HTTPConnection object at 0xffffac5c48e0>: Failed to establish a new connection: [Errno 111] Connection refused'))
2025-02-26 13:34:57,537 data_to_fw.py ERROR: Error : HTTPConnectionPool(host='127.0.0.1', port=7077): Max retries exceeded with url: /fwvision/qcinspection/update_qc_order (Caused by NewConnectionError('<urllib3.connection.HTTPConnection object at 0xffffac5ac4f0>: Failed to establish a new connection: [Errno 111] Connection refused'))
2025-02-26 13:35:01,230 data_to_fw.py ERROR: Error : HTTPConnectionPool(host='127.0.0.1', port=7077): Max retries exceeded with url: /fwvision/qcinspection/update_qc_order (Caused by NewConnectionError('<urllib3.connection.HTTPConnection object at 0xffffac5acfa0>: Failed to establish a new connection: [Errno 111] Connection refused'))
2025-02-26 13:35:04,943 data_to_fw.py ERROR: Error : HTTPConnectionPool(host='127.0.0.1', port=7077): Max retries exceeded with url: /fwvision/qcinspection/update_qc_order (Caused by NewConnectionError('<urllib3.connection.HTTPConnection object at 0xffffac5b9fa0>: Failed to establish a new connection: [Errno 111] Connection refused'))
2025-02-26 13:35:08,939 data_to_fw.py ERROR: Error : HTTPConnectionPool(host='127.0.0.1', port=7077): Max retries exceeded with url: /fwvision/qcinspection/update_qc_order (Caused by NewConnectionError('<urllib3.connection.HTTPConnection object at 0xffffac5c4250>: Failed to establish a new connection: [Errno 111] Connection refused'))
2025-02-26 13:35:12,664 data_to_fw.py ERROR: Error : HTTPConnectionPool(host='127.0.0.1', port=7077): Max retries exceeded with url: /fwvision/qcinspection/update_qc_order (Caused by NewConnectionError('<urllib3.connection.HTTPConnection object at 0xffffac5acaf0>: Failed to establish a new connection: [Errno 111] Connection refused'))
2025-02-26 13:35:16,365 data_to_fw.py ERROR: Error : HTTPConnectionPool(host='127.0.0.1', port=7077): Max retries exceeded with url: /fwvision/qcinspection/update_qc_order (Caused by NewConnectionError('<urllib3.connection.HTTPConnection object at 0xffffac5ac5e0>: Failed to establish a new connection: [Errno 111] Connection refused'))
2025-02-26 13:35:20,074 data_to_fw.py ERROR: Error : HTTPConnectionPool(host='127.0.0.1', port=7077): Max retries exceeded with url: /fwvision/qcinspection/update_qc_order (Caused by NewConnectionError('<urllib3.connection.HTTPConnection object at 0xffffac5b9e20>: Failed to establish a new connection: [Errno 111] Connection refused'))
2025-02-26 13:35:24,081 data_to_fw.py ERROR: Error : HTTPConnectionPool(host='127.0.0.1', port=7077): Max retries exceeded with url: /fwvision/qcinspection/update_qc_order (Caused by NewConnectionError('<urllib3.connection.HTTPConnection object at 0xffffac63b670>: Failed to establish a new connection: [Errno 111] Connection refused'))
2025-02-26 13:35:27,790 data_to_fw.py ERROR: Error : HTTPConnectionPool(host='127.0.0.1', port=7077): Max retries exceeded with url: /fwvision/qcinspection/update_qc_order (Caused by NewConnectionError('<urllib3.connection.HTTPConnection object at 0xffffac5b9f70>: Failed to establish a new connection: [Errno 111] Connection refused'))
2025-02-26 13:35:31,495 data_to_fw.py ERROR: Error : HTTPConnectionPool(host='127.0.0.1', port=7077): Max retries exceeded with url: /fwvision/qcinspection/update_qc_order (Caused by NewConnectionError('<urllib3.connection.HTTPConnection object at 0xffffac5acdc0>: Failed to establish a new connection: [Errno 111] Connection refused'))
2025-02-26 13:35:35,225 data_to_fw.py ERROR: Error : HTTPConnectionPool(host='127.0.0.1', port=7077): Max retries exceeded with url: /fwvision/qcinspection/update_qc_order (Caused by NewConnectionError('<urllib3.connection.HTTPConnection object at 0xffffac5ac430>: Failed to establish a new connection: [Errno 111] Connection refused'))
2025-02-26 13:35:39,232 data_to_fw.py ERROR: Error : HTTPConnectionPool(host='127.0.0.1', port=7077): Max retries exceeded with url: /fwvision/qcinspection/update_qc_order (Caused by NewConnectionError('<urllib3.connection.HTTPConnection object at 0xffffac5c4f70>: Failed to establish a new connection: [Errno 111] Connection refused'))
2025-02-26 13:35:42,939 data_to_fw.py ERROR: Error : HTTPConnectionPool(host='127.0.0.1', port=7077): Max retries exceeded with url: /fwvision/qcinspection/update_qc_order (Caused by NewConnectionError('<urllib3.connection.HTTPConnection object at 0xffffac617bb0>: Failed to establish a new connection: [Errno 111] Connection refused'))
2025-02-26 13:35:46,646 data_to_fw.py ERROR: Error : HTTPConnectionPool(host='127.0.0.1', port=7077): Max retries exceeded with url: /fwvision/qcinspection/update_qc_order (Caused by NewConnectionError('<urllib3.connection.HTTPConnection object at 0xffffac63b910>: Failed to establish a new connection: [Errno 111] Connection refused'))
2025-02-26 13:35:50,348 data_to_fw.py ERROR: Error : HTTPConnectionPool(host='127.0.0.1', port=7077): Max retries exceeded with url: /fwvision/qcinspection/update_qc_order (Caused by NewConnectionError('<urllib3.connection.HTTPConnection object at 0xffffac5ac820>: Failed to establish a new connection: [Errno 111] Connection refused'))
2025-02-26 13:36:51,367 data_to_fw.py ERROR: Error : HTTPConnectionPool(host='127.0.0.1', port=7077): Max retries exceeded with url: /fwvision/qcinspection/update_qc_order (Caused by NewConnectionError('<urllib3.connection.HTTPConnection object at 0xffffac5c4c10>: Failed to establish a new connection: [Errno 111] Connection refused'))
2025-02-26 13:36:55,082 data_to_fw.py ERROR: Error : HTTPConnectionPool(host='127.0.0.1', port=7077): Max retries exceeded with url: /fwvision/qcinspection/update_qc_order (Caused by NewConnectionError('<urllib3.connection.HTTPConnection object at 0xffffac5c4e80>: Failed to establish a new connection: [Errno 111] Connection refused'))
2025-02-26 13:36:58,781 data_to_fw.py ERROR: Error : HTTPConnectionPool(host='127.0.0.1', port=7077): Max retries exceeded with url: /fwvision/qcinspection/update_qc_order (Caused by NewConnectionError('<urllib3.connection.HTTPConnection object at 0xffffac63b0d0>: Failed to establish a new connection: [Errno 111] Connection refused'))
2025-02-26 13:37:02,477 data_to_fw.py ERROR: Error : HTTPConnectionPool(host='127.0.0.1', port=7077): Max retries exceeded with url: /fwvision/qcinspection/update_qc_order (Caused by NewConnectionError('<urllib3.connection.HTTPConnection object at 0xffffac5b96a0>: Failed to establish a new connection: [Errno 111] Connection refused'))
2025-02-26 13:37:06,470 data_to_fw.py ERROR: Error : HTTPConnectionPool(host='127.0.0.1', port=7077): Max retries exceeded with url: /fwvision/qcinspection/update_qc_order (Caused by NewConnectionError('<urllib3.connection.HTTPConnection object at 0xffffac63b1c0>: Failed to establish a new connection: [Errno 111] Connection refused'))
2025-02-26 13:37:10,161 data_to_fw.py ERROR: Error : HTTPConnectionPool(host='127.0.0.1', port=7077): Max retries exceeded with url: /fwvision/qcinspection/update_qc_order (Caused by NewConnectionError('<urllib3.connection.HTTPConnection object at 0xffffac63b5e0>: Failed to establish a new connection: [Errno 111] Connection refused'))
2025-02-26 13:37:13,861 data_to_fw.py ERROR: Error : HTTPConnectionPool(host='127.0.0.1', port=7077): Max retries exceeded with url: /fwvision/qcinspection/update_qc_order (Caused by NewConnectionError('<urllib3.connection.HTTPConnection object at 0xffffac5c4460>: Failed to establish a new connection: [Errno 111] Connection refused'))
2025-02-26 13:37:17,575 data_to_fw.py ERROR: Error : HTTPConnectionPool(host='127.0.0.1', port=7077): Max retries exceeded with url: /fwvision/qcinspection/update_qc_order (Caused by NewConnectionError('<urllib3.connection.HTTPConnection object at 0xffffac5aceb0>: Failed to establish a new connection: [Errno 111] Connection refused'))
2025-02-26 13:37:21,593 data_to_fw.py ERROR: Error : HTTPConnectionPool(host='127.0.0.1', port=7077): Max retries exceeded with url: /fwvision/qcinspection/update_qc_order (Caused by NewConnectionError('<urllib3.connection.HTTPConnection object at 0xffffac5acd60>: Failed to establish a new connection: [Errno 111] Connection refused'))
2025-02-26 13:37:25,301 data_to_fw.py ERROR: Error : HTTPConnectionPool(host='127.0.0.1', port=7077): Max retries exceeded with url: /fwvision/qcinspection/update_qc_order (Caused by NewConnectionError('<urllib3.connection.HTTPConnection object at 0xffffac5b9490>: Failed to establish a new connection: [Errno 111] Connection refused'))
2025-02-26 13:37:29,044 data_to_fw.py ERROR: Error : HTTPConnectionPool(host='127.0.0.1', port=7077): Max retries exceeded with url: /fwvision/qcinspection/update_qc_order (Caused by NewConnectionError('<urllib3.connection.HTTPConnection object at 0xffffac5c4070>: Failed to establish a new connection: [Errno 111] Connection refused'))
2025-02-26 13:37:32,771 data_to_fw.py ERROR: Error : HTTPConnectionPool(host='127.0.0.1', port=7077): Max retries exceeded with url: /fwvision/qcinspection/update_qc_order (Caused by NewConnectionError('<urllib3.connection.HTTPConnection object at 0xffffac63b820>: Failed to establish a new connection: [Errno 111] Connection refused'))
2025-02-26 13:37:36,770 data_to_fw.py ERROR: Error : HTTPConnectionPool(host='127.0.0.1', port=7077): Max retries exceeded with url: /fwvision/qcinspection/update_qc_order (Caused by NewConnectionError('<urllib3.connection.HTTPConnection object at 0xffffac63bbe0>: Failed to establish a new connection: [Errno 111] Connection refused'))
2025-02-26 13:37:40,472 data_to_fw.py ERROR: Error : HTTPConnectionPool(host='127.0.0.1', port=7077): Max retries exceeded with url: /fwvision/qcinspection/update_qc_order (Caused by NewConnectionError('<urllib3.connection.HTTPConnection object at 0xffffac5b9f40>: Failed to establish a new connection: [Errno 111] Connection refused'))
2025-02-26 13:37:44,169 data_to_fw.py ERROR: Error : HTTPConnectionPool(host='127.0.0.1', port=7077): Max retries exceeded with url: /fwvision/qcinspection/update_qc_order (Caused by NewConnectionError('<urllib3.connection.HTTPConnection object at 0xffffac5ac400>: Failed to establish a new connection: [Errno 111] Connection refused'))
2025-02-26 13:37:47,884 data_to_fw.py ERROR: Error : HTTPConnectionPool(host='127.0.0.1', port=7077): Max retries exceeded with url: /fwvision/qcinspection/update_qc_order (Caused by NewConnectionError('<urllib3.connection.HTTPConnection object at 0xffffac63b1f0>: Failed to establish a new connection: [Errno 111] Connection refused'))
2025-02-26 13:37:51,862 data_to_fw.py ERROR: Error : HTTPConnectionPool(host='127.0.0.1', port=7077): Max retries exceeded with url: /fwvision/qcinspection/update_qc_order (Caused by NewConnectionError('<urllib3.connection.HTTPConnection object at 0xffffac63b370>: Failed to establish a new connection: [Errno 111] Connection refused'))
2025-02-26 13:37:55,589 data_to_fw.py ERROR: Error : HTTPConnectionPool(host='127.0.0.1', port=7077): Max retries exceeded with url: /fwvision/qcinspection/update_qc_order (Caused by NewConnectionError('<urllib3.connection.HTTPConnection object at 0xffffac5c4820>: Failed to establish a new connection: [Errno 111] Connection refused'))
2025-02-26 13:37:59,291 data_to_fw.py ERROR: Error : HTTPConnectionPool(host='127.0.0.1', port=7077): Max retries exceeded with url: /fwvision/qcinspection/update_qc_order (Caused by NewConnectionError('<urllib3.connection.HTTPConnection object at 0xffffac5c4c40>: Failed to establish a new connection: [Errno 111] Connection refused'))
2025-02-26 13:38:02,985 data_to_fw.py ERROR: Error : HTTPConnectionPool(host='127.0.0.1', port=7077): Max retries exceeded with url: /fwvision/qcinspection/update_qc_order (Caused by NewConnectionError('<urllib3.connection.HTTPConnection object at 0xffffac63b0d0>: Failed to establish a new connection: [Errno 111] Connection refused'))
2025-02-26 13:38:06,986 data_to_fw.py ERROR: Error : HTTPConnectionPool(host='127.0.0.1', port=7077): Max retries exceeded with url: /fwvision/qcinspection/update_qc_order (Caused by NewConnectionError('<urllib3.connection.HTTPConnection object at 0xffffac5c4310>: Failed to establish a new connection: [Errno 111] Connection refused'))
2025-02-26 13:38:10,689 data_to_fw.py ERROR: Error : HTTPConnectionPool(host='127.0.0.1', port=7077): Max retries exceeded with url: /fwvision/qcinspection/update_qc_order (Caused by NewConnectionError('<urllib3.connection.HTTPConnection object at 0xffffac5b9b80>: Failed to establish a new connection: [Errno 111] Connection refused'))
2025-02-26 13:38:14,387 data_to_fw.py ERROR: Error : HTTPConnectionPool(host='127.0.0.1', port=7077): Max retries exceeded with url: /fwvision/qcinspection/update_qc_order (Caused by NewConnectionError('<urllib3.connection.HTTPConnection object at 0xffffac5b9700>: Failed to establish a new connection: [Errno 111] Connection refused'))
2025-02-26 13:38:18,101 data_to_fw.py ERROR: Error : HTTPConnectionPool(host='127.0.0.1', port=7077): Max retries exceeded with url: /fwvision/qcinspection/update_qc_order (Caused by NewConnectionError('<urllib3.connection.HTTPConnection object at 0xffffac5acd00>: Failed to establish a new connection: [Errno 111] Connection refused'))
2025-02-26 13:38:22,137 data_to_fw.py ERROR: Error : HTTPConnectionPool(host='127.0.0.1', port=7077): Max retries exceeded with url: /fwvision/qcinspection/update_qc_order (Caused by NewConnectionError('<urllib3.connection.HTTPConnection object at 0xffffac5b9df0>: Failed to establish a new connection: [Errno 111] Connection refused'))
2025-02-26 13:38:25,843 data_to_fw.py ERROR: Error : HTTPConnectionPool(host='127.0.0.1', port=7077): Max retries exceeded with url: /fwvision/qcinspection/update_qc_order (Caused by NewConnectionError('<urllib3.connection.HTTPConnection object at 0xffffac63b760>: Failed to establish a new connection: [Errno 111] Connection refused'))
2025-02-26 13:38:29,535 data_to_fw.py ERROR: Error : HTTPConnectionPool(host='127.0.0.1', port=7077): Max retries exceeded with url: /fwvision/qcinspection/update_qc_order (Caused by NewConnectionError('<urllib3.connection.HTTPConnection object at 0xffffac63b700>: Failed to establish a new connection: [Errno 111] Connection refused'))
2025-02-26 13:38:33,229 data_to_fw.py ERROR: Error : HTTPConnectionPool(host='127.0.0.1', port=7077): Max retries exceeded with url: /fwvision/qcinspection/update_qc_order (Caused by NewConnectionError('<urllib3.connection.HTTPConnection object at 0xffffac5ac5b0>: Failed to establish a new connection: [Errno 111] Connection refused'))
2025-02-26 13:38:37,223 data_to_fw.py ERROR: Error : HTTPConnectionPool(host='127.0.0.1', port=7077): Max retries exceeded with url: /fwvision/qcinspection/update_qc_order (Caused by NewConnectionError('<urllib3.connection.HTTPConnection object at 0xffffac644fd0>: Failed to establish a new connection: [Errno 111] Connection refused'))
2025-02-26 13:38:40,915 data_to_fw.py ERROR: Error : HTTPConnectionPool(host='127.0.0.1', port=7077): Max retries exceeded with url: /fwvision/qcinspection/update_qc_order (Caused by NewConnectionError('<urllib3.connection.HTTPConnection object at 0xffffac63bac0>: Failed to establish a new connection: [Errno 111] Connection refused'))
2025-02-26 13:38:44,611 data_to_fw.py ERROR: Error : HTTPConnectionPool(host='127.0.0.1', port=7077): Max retries exceeded with url: /fwvision/qcinspection/update_qc_order (Caused by NewConnectionError('<urllib3.connection.HTTPConnection object at 0xffffac63b790>: Failed to establish a new connection: [Errno 111] Connection refused'))
2025-02-26 13:38:48,308 data_to_fw.py ERROR: Error : HTTPConnectionPool(host='127.0.0.1', port=7077): Max retries exceeded with url: /fwvision/qcinspection/update_qc_order (Caused by NewConnectionError('<urllib3.connection.HTTPConnection object at 0xffffac5ac2e0>: Failed to establish a new connection: [Errno 111] Connection refused'))
2025-02-26 13:38:52,325 data_to_fw.py ERROR: Error : HTTPConnectionPool(host='127.0.0.1', port=7077): Max retries exceeded with url: /fwvision/qcinspection/update_qc_order (Caused by NewConnectionError('<urllib3.connection.HTTPConnection object at 0xffffac5b9700>: Failed to establish a new connection: [Errno 111] Connection refused'))
2025-02-26 13:38:56,075 data_to_fw.py ERROR: Error : HTTPConnectionPool(host='127.0.0.1', port=7077): Max retries exceeded with url: /fwvision/qcinspection/update_qc_order (Caused by NewConnectionError('<urllib3.connection.HTTPConnection object at 0xffffac5b92e0>: Failed to establish a new connection: [Errno 111] Connection refused'))
2025-02-26 13:38:59,770 data_to_fw.py ERROR: Error : HTTPConnectionPool(host='127.0.0.1', port=7077): Max retries exceeded with url: /fwvision/qcinspection/update_qc_order (Caused by NewConnectionError('<urllib3.connection.HTTPConnection object at 0xffffac5b9340>: Failed to establish a new connection: [Errno 111] Connection refused'))
2025-02-26 13:39:03,467 data_to_fw.py ERROR: Error : HTTPConnectionPool(host='127.0.0.1', port=7077): Max retries exceeded with url: /fwvision/qcinspection/update_qc_order (Caused by NewConnectionError('<urllib3.connection.HTTPConnection object at 0xffffac5ac3d0>: Failed to establish a new connection: [Errno 111] Connection refused'))
2025-02-26 13:39:07,462 data_to_fw.py ERROR: Error : HTTPConnectionPool(host='127.0.0.1', port=7077): Max retries exceeded with url: /fwvision/qcinspection/update_qc_order (Caused by NewConnectionError('<urllib3.connection.HTTPConnection object at 0xffffac63b880>: Failed to establish a new connection: [Errno 111] Connection refused'))
2025-02-26 13:39:11,162 data_to_fw.py ERROR: Error : HTTPConnectionPool(host='127.0.0.1', port=7077): Max retries exceeded with url: /fwvision/qcinspection/update_qc_order (Caused by NewConnectionError('<urllib3.connection.HTTPConnection object at 0xffffac5c4490>: Failed to establish a new connection: [Errno 111] Connection refused'))
2025-02-26 13:39:14,856 data_to_fw.py ERROR: Error : HTTPConnectionPool(host='127.0.0.1', port=7077): Max retries exceeded with url: /fwvision/qcinspection/update_qc_order (Caused by NewConnectionError('<urllib3.connection.HTTPConnection object at 0xffffac617100>: Failed to establish a new connection: [Errno 111] Connection refused'))
2025-02-26 13:39:18,555 data_to_fw.py ERROR: Error : HTTPConnectionPool(host='127.0.0.1', port=7077): Max retries exceeded with url: /fwvision/qcinspection/update_qc_order (Caused by NewConnectionError('<urllib3.connection.HTTPConnection object at 0xffffac5c4f40>: Failed to establish a new connection: [Errno 111] Connection refused'))
2025-02-26 13:39:22,554 data_to_fw.py ERROR: Error : HTTPConnectionPool(host='127.0.0.1', port=7077): Max retries exceeded with url: /fwvision/qcinspection/update_qc_order (Caused by NewConnectionError('<urllib3.connection.HTTPConnection object at 0xffffac5ac850>: Failed to establish a new connection: [Errno 111] Connection refused'))
2025-02-26 13:39:26,270 data_to_fw.py ERROR: Error : HTTPConnectionPool(host='127.0.0.1', port=7077): Max retries exceeded with url: /fwvision/qcinspection/update_qc_order (Caused by NewConnectionError('<urllib3.connection.HTTPConnection object at 0xffffac63bd90>: Failed to establish a new connection: [Errno 111] Connection refused'))
2025-02-26 13:39:29,991 data_to_fw.py ERROR: Error : HTTPConnectionPool(host='127.0.0.1', port=7077): Max retries exceeded with url: /fwvision/qcinspection/update_qc_order (Caused by NewConnectionError('<urllib3.connection.HTTPConnection object at 0xffffac617f10>: Failed to establish a new connection: [Errno 111] Connection refused'))
2025-02-26 13:39:33,687 data_to_fw.py ERROR: Error : HTTPConnectionPool(host='127.0.0.1', port=7077): Max retries exceeded with url: /fwvision/qcinspection/update_qc_order (Caused by NewConnectionError('<urllib3.connection.HTTPConnection object at 0xffffac5b94f0>: Failed to establish a new connection: [Errno 111] Connection refused'))
2025-02-26 13:39:37,680 data_to_fw.py ERROR: Error : HTTPConnectionPool(host='127.0.0.1', port=7077): Max retries exceeded with url: /fwvision/qcinspection/update_qc_order (Caused by NewConnectionError('<urllib3.connection.HTTPConnection object at 0xffffac644220>: Failed to establish a new connection: [Errno 111] Connection refused'))
2025-02-26 13:39:41,387 data_to_fw.py ERROR: Error : HTTPConnectionPool(host='127.0.0.1', port=7077): Max retries exceeded with url: /fwvision/qcinspection/update_qc_order (Caused by NewConnectionError('<urllib3.connection.HTTPConnection object at 0xffffac63b460>: Failed to establish a new connection: [Errno 111] Connection refused'))
2025-02-26 13:39:45,121 data_to_fw.py ERROR: Error : HTTPConnectionPool(host='127.0.0.1', port=7077): Max retries exceeded with url: /fwvision/qcinspection/update_qc_order (Caused by NewConnectionError('<urllib3.connection.HTTPConnection object at 0xffffac5ac940>: Failed to establish a new connection: [Errno 111] Connection refused'))
2025-02-26 13:39:48,825 data_to_fw.py ERROR: Error : HTTPConnectionPool(host='127.0.0.1', port=7077): Max retries exceeded with url: /fwvision/qcinspection/update_qc_order (Caused by NewConnectionError('<urllib3.connection.HTTPConnection object at 0xffffac6447f0>: Failed to establish a new connection: [Errno 111] Connection refused'))
2025-02-26 13:39:52,835 data_to_fw.py ERROR: Error : HTTPConnectionPool(host='127.0.0.1', port=7077): Max retries exceeded with url: /fwvision/qcinspection/update_qc_order (Caused by NewConnectionError('<urllib3.connection.HTTPConnection object at 0xffffac5c4730>: Failed to establish a new connection: [Errno 111] Connection refused'))
2025-02-26 13:39:56,532 data_to_fw.py ERROR: Error : HTTPConnectionPool(host='127.0.0.1', port=7077): Max retries exceeded with url: /fwvision/qcinspection/update_qc_order (Caused by NewConnectionError('<urllib3.connection.HTTPConnection object at 0xffffac5b9c10>: Failed to establish a new connection: [Errno 111] Connection refused'))
2025-02-26 13:40:00,255 data_to_fw.py ERROR: Error : HTTPConnectionPool(host='127.0.0.1', port=7077): Max retries exceeded with url: /fwvision/qcinspection/update_qc_order (Caused by NewConnectionError('<urllib3.connection.HTTPConnection object at 0xffffac5b9c40>: Failed to establish a new connection: [Errno 111] Connection refused'))
2025-02-26 13:40:03,990 data_to_fw.py ERROR: Error : HTTPConnectionPool(host='127.0.0.1', port=7077): Max retries exceeded with url: /fwvision/qcinspection/update_qc_order (Caused by NewConnectionError('<urllib3.connection.HTTPConnection object at 0xffffac6441f0>: Failed to establish a new connection: [Errno 111] Connection refused'))
2025-02-26 13:40:07,999 data_to_fw.py ERROR: Error : HTTPConnectionPool(host='127.0.0.1', port=7077): Max retries exceeded with url: /fwvision/qcinspection/update_qc_order (Caused by NewConnectionError('<urllib3.connection.HTTPConnection object at 0xffffac5ac5b0>: Failed to establish a new connection: [Errno 111] Connection refused'))
2025-02-26 13:40:11,703 data_to_fw.py ERROR: Error : HTTPConnectionPool(host='127.0.0.1', port=7077): Max retries exceeded with url: /fwvision/qcinspection/update_qc_order (Caused by NewConnectionError('<urllib3.connection.HTTPConnection object at 0xffffac63bac0>: Failed to establish a new connection: [Errno 111] Connection refused'))
2025-02-26 13:40:15,409 data_to_fw.py ERROR: Error : HTTPConnectionPool(host='127.0.0.1', port=7077): Max retries exceeded with url: /fwvision/qcinspection/update_qc_order (Caused by NewConnectionError('<urllib3.connection.HTTPConnection object at 0xffffac617d60>: Failed to establish a new connection: [Errno 111] Connection refused'))
2025-02-26 13:40:19,096 data_to_fw.py ERROR: Error : HTTPConnectionPool(host='127.0.0.1', port=7077): Max retries exceeded with url: /fwvision/qcinspection/update_qc_order (Caused by NewConnectionError('<urllib3.connection.HTTPConnection object at 0xffffac617040>: Failed to establish a new connection: [Errno 111] Connection refused'))
2025-02-26 13:40:23,090 data_to_fw.py ERROR: Error : HTTPConnectionPool(host='127.0.0.1', port=7077): Max retries exceeded with url: /fwvision/qcinspection/update_qc_order (Caused by NewConnectionError('<urllib3.connection.HTTPConnection object at 0xffffac63b070>: Failed to establish a new connection: [Errno 111] Connection refused'))
2025-02-26 13:40:26,790 data_to_fw.py ERROR: Error : HTTPConnectionPool(host='127.0.0.1', port=7077): Max retries exceeded with url: /fwvision/qcinspection/update_qc_order (Caused by NewConnectionError('<urllib3.connection.HTTPConnection object at 0xffffac5c4370>: Failed to establish a new connection: [Errno 111] Connection refused'))
2025-02-26 13:40:30,497 data_to_fw.py ERROR: Error : HTTPConnectionPool(host='127.0.0.1', port=7077): Max retries exceeded with url: /fwvision/qcinspection/update_qc_order (Caused by NewConnectionError('<urllib3.connection.HTTPConnection object at 0xffffac5ac760>: Failed to establish a new connection: [Errno 111] Connection refused'))
2025-02-26 13:40:34,189 data_to_fw.py ERROR: Error : HTTPConnectionPool(host='127.0.0.1', port=7077): Max retries exceeded with url: /fwvision/qcinspection/update_qc_order (Caused by NewConnectionError('<urllib3.connection.HTTPConnection object at 0xffffac5b9d30>: Failed to establish a new connection: [Errno 111] Connection refused'))
2025-02-26 13:40:38,199 data_to_fw.py ERROR: Error : HTTPConnectionPool(host='127.0.0.1', port=7077): Max retries exceeded with url: /fwvision/qcinspection/update_qc_order (Caused by NewConnectionError('<urllib3.connection.HTTPConnection object at 0xffffacee1700>: Failed to establish a new connection: [Errno 111] Connection refused'))
2025-02-26 13:40:41,933 data_to_fw.py ERROR: Error : HTTPConnectionPool(host='127.0.0.1', port=7077): Max retries exceeded with url: /fwvision/qcinspection/update_qc_order (Caused by NewConnectionError('<urllib3.connection.HTTPConnection object at 0xffffac5ac070>: Failed to establish a new connection: [Errno 111] Connection refused'))
2025-02-26 13:40:45,641 data_to_fw.py ERROR: Error : HTTPConnectionPool(host='127.0.0.1', port=7077): Max retries exceeded with url: /fwvision/qcinspection/update_qc_order (Caused by NewConnectionError('<urllib3.connection.HTTPConnection object at 0xffffac63b610>: Failed to establish a new connection: [Errno 111] Connection refused'))
2025-02-26 13:40:49,348 data_to_fw.py ERROR: Error : HTTPConnectionPool(host='127.0.0.1', port=7077): Max retries exceeded with url: /fwvision/qcinspection/update_qc_order (Caused by NewConnectionError('<urllib3.connection.HTTPConnection object at 0xffffac63beb0>: Failed to establish a new connection: [Errno 111] Connection refused'))
2025-02-26 13:40:53,356 data_to_fw.py ERROR: Error : HTTPConnectionPool(host='127.0.0.1', port=7077): Max retries exceeded with url: /fwvision/qcinspection/update_qc_order (Caused by NewConnectionError('<urllib3.connection.HTTPConnection object at 0xffffac617f70>: Failed to establish a new connection: [Errno 111] Connection refused'))
2025-02-26 13:40:57,064 data_to_fw.py ERROR: Error : HTTPConnectionPool(host='127.0.0.1', port=7077): Max retries exceeded with url: /fwvision/qcinspection/update_qc_order (Caused by NewConnectionError('<urllib3.connection.HTTPConnection object at 0xffffac5b9ca0>: Failed to establish a new connection: [Errno 111] Connection refused'))
2025-02-26 13:41:00,775 data_to_fw.py ERROR: Error : HTTPConnectionPool(host='127.0.0.1', port=7077): Max retries exceeded with url: /fwvision/qcinspection/update_qc_order (Caused by NewConnectionError('<urllib3.connection.HTTPConnection object at 0xffffac617ca0>: Failed to establish a new connection: [Errno 111] Connection refused'))
2025-02-26 13:41:04,482 data_to_fw.py ERROR: Error : HTTPConnectionPool(host='127.0.0.1', port=7077): Max retries exceeded with url: /fwvision/qcinspection/update_qc_order (Caused by NewConnectionError('<urllib3.connection.HTTPConnection object at 0xffffac63beb0>: Failed to establish a new connection: [Errno 111] Connection refused'))
2025-02-26 13:41:08,484 data_to_fw.py ERROR: Error : HTTPConnectionPool(host='127.0.0.1', port=7077): Max retries exceeded with url: /fwvision/qcinspection/update_qc_order (Caused by NewConnectionError('<urllib3.connection.HTTPConnection object at 0xffffac5acaf0>: Failed to establish a new connection: [Errno 111] Connection refused'))
2025-02-26 13:41:12,192 data_to_fw.py ERROR: Error : HTTPConnectionPool(host='127.0.0.1', port=7077): Max retries exceeded with url: /fwvision/qcinspection/update_qc_order (Caused by NewConnectionError('<urllib3.connection.HTTPConnection object at 0xffffac644520>: Failed to establish a new connection: [Errno 111] Connection refused'))
2025-02-26 13:41:15,905 data_to_fw.py ERROR: Error : HTTPConnectionPool(host='127.0.0.1', port=7077): Max retries exceeded with url: /fwvision/qcinspection/update_qc_order (Caused by NewConnectionError('<urllib3.connection.HTTPConnection object at 0xffffac5c4d90>: Failed to establish a new connection: [Errno 111] Connection refused'))
2025-02-26 13:41:19,625 data_to_fw.py ERROR: Error : HTTPConnectionPool(host='127.0.0.1', port=7077): Max retries exceeded with url: /fwvision/qcinspection/update_qc_order (Caused by NewConnectionError('<urllib3.connection.HTTPConnection object at 0xffffac644760>: Failed to establish a new connection: [Errno 111] Connection refused'))
2025-02-26 16:52:10,219 data_to_fw.py ERROR: Error sending data to device. Status code: 404
2025-02-26 16:52:13,942 data_to_fw.py ERROR: Error sending data to device. Status code: 404
2025-02-26 16:52:17,677 data_to_fw.py ERROR: Error sending data to device. Status code: 404
2025-02-26 16:52:21,397 data_to_fw.py ERROR: Error sending data to device. Status code: 404
2025-02-27 09:10:03,606 capture_img.py ERROR: Order info is incomplete.
2025-02-27 09:10:03,615 capture_img.py ERROR: Order data missing, cannot capture image.
2025-02-27 09:15:38,887 capture_img.py ERROR: Order info is incomplete.
2025-02-27 09:15:38,888 capture_img.py ERROR: Order data missing, cannot capture image.
2025-02-27 17:06:44,029 capture_img.py ERROR: Order info is incomplete.
2025-02-27 17:06:44,037 capture_img.py ERROR: Order data missing, cannot capture image.
2025-02-27 17:07:02,524 capture_img.py ERROR: Order info is incomplete.
2025-02-27 17:07:02,524 capture_img.py ERROR: Order data missing, cannot capture image.
2025-02-27 17:07:26,426 capture_img.py ERROR: Order info is incomplete.
2025-02-27 17:07:26,426 capture_img.py ERROR: Order data missing, cannot capture image.
2025-02-27 17:07:47,725 capture_img.py ERROR: Order info is incomplete.
2025-02-27 17:07:47,725 capture_img.py ERROR: Order data missing, cannot capture image.
2025-02-27 17:11:40,379 capture_img.py ERROR: Error getting order info: HTTPConnectionPool(host='127.0.0.1', port=7077): Max retries exceeded with url: /fwvision/home/get_payload_data (Caused by NewConnectionError('<urllib3.connection.HTTPConnection object at 0xffffaccc61c0>: Failed to establish a new connection: [Errno 111] Connection refused'))
2025-02-27 17:11:40,382 capture_img.py ERROR: Order data missing, cannot capture image.
2025-02-28 10:40:08,602 capture_img.py ERROR: Error getting order info: HTTPConnectionPool(host='127.0.0.1', port=7077): Max retries exceeded with url: /fwvision/home/get_payload_data (Caused by NewConnectionError('<urllib3.connection.HTTPConnection object at 0xffff8d7331c0>: Failed to establish a new connection: [Errno 111] Connection refused'))
2025-02-28 10:40:08,603 capture_img.py ERROR: Order data missing, cannot capture image.
2025-02-28 16:55:50,406 capture_img.py ERROR: Error getting order info: HTTPConnectionPool(host='127.0.0.1', port=7077): Max retries exceeded with url: /fwvision/home/get_payload_data (Caused by NewConnectionError('<urllib3.connection.HTTPConnection object at 0xffffb9f671c0>: Failed to establish a new connection: [Errno 111] Connection refused'))
2025-02-28 16:55:50,412 capture_img.py ERROR: Order data missing, cannot capture image.
